Workbook

Sheet Start Here
A1: Macro Tracker — Layer 1 (Macro Permission)
A2: Purpose: one weekly bias per instrument — LONG / SHORT / FLAT — with an expiry date. This is a filter, never an entry signal.
A4: WEEKLY ROUTINE | E4: SHEET INDEX
A5: 1. Scorecard: update the blue cells for USD, EUR, GBP, JPY (only what changed since last week). | E5: Sheet (click to open) | F5: What it's for | G5: When
A6: 2. Risk & Gold: update VIX, S&P 500 vs 200-day, real yield, dollar index, and your own gold research score. | E6: Bias ↗ | F6: FINAL BIAS per pair — what Layers 2–4 may trade | G6: Read weekly
A7: 3. Bias: read the FINAL BIAS column. Enter today's date in 'Last reviewed' and write the invalidation. | E7: Compare ↗ | F7: Two currencies side by side — does the evidence back the call? | G7: Before a new idea
A8: 4. Journal: log one line per instrument — bias, key driver, next catalyst. | E8: Scorecard ↗ | F8: Macro data per currency → −1/0/+1 scores and stance | G8: Fill weekly
A9: 4b. Hub: fill the risk barometer, refresh the one-line story for each currency you trade, glance at section B once a month. | E9: Risk & Gold ↗ | F9: VIX risk regime + gold drivers → gold bias | G9: Fill weekly
A10: 5. After tier-1 events (CPI, jobs, central-bank meetings): re-check only the affected currency. | E10: Key Levels ↗ | F10: Price levels where big players acted, with distance to price | G10: Fill weekly
E11: Hub ↗ | F11: Links out + one-line story per currency, risk barometer | G11: Fill weekly / monthly
A12: UNITS & CONVENTIONS | E12: Journal ↗ | F12: One row per bias — becomes your tuning data | G12: Log weekly
A13: • Percentages are typed as plain numbers: 3.1 means 3.1%.
A14: • Yield changes are in basis points (bp): 100 bp = 1 percentage point. | E14: COLOUR LEGEND
A15: • Text that starts with 'EXAMPLE:' is illustrative — overwrite it with your own read. | E15: CELL TYPES — what you may touch
A16: • Dates: type them as dates (e.g. 21-9-2026), never as a formula like =TODAY(). | E16: 3.10 | F16: Input — type here | G16: Every sheet
E17: 1 | F17: Formula — calculated, don't overwrite | G17: Every sheet
A18: RULES / THRESHOLDS (every formula reads from here) | E18: -1 | F18: Linked — pulled from another sheet | G18: Bias, Compare, Risk & Gold, Hub
A19: Rule | B19: Value | C19: What it does | E19: Column header | F19: Table header | G19: Every sheet
A20: Inflation 'near target' band (pp) | B20: 0.5 | C20: Core CPI falling AND within this distance of target (or below) = −1. Above target and not falling = +1. | E20: Fed ↗ | F20: Hyperlink — opens a website or sheet | G20: Hub, this sheet
A21: Unemployment change (pp) | B21: 0.2 | C21: Unemployment down ≥ this over 3 months = +1 (tight). Up ≥ this = −1 (weakening). | E21: Help text | F21: Note / explanation — read only | G21: Every sheet
A22: PMI expansion level | B22: 52 | C22: Composite PMI ≥ this = +1. | E22: ⚠ Warning | F22: Warning — check before relying on it | G22: Scorecard, Key Levels
A23: PMI contraction level | B23: 48 | C23: Composite PMI ≤ this = −1. | E23: — | F23: Not applicable for this row | G23: Bias (gold row)
A24: 2Y yield move (bp, 1 month) | B24: 15 | C24: Market repricing proxy. 2Y up ≥ this = +1 (hawkish repricing), down ≥ this = −1. | E24: Give me a brief… | F24: Prompt — copy and paste into Claude | G24: Hub
A25: Currency stance cut-off (score) | B25: 2 | C25: Total ≥ +2 = HAWKISH, ≤ −2 = DOVISH, otherwise NEUTRAL. | E25: SIGNALS — colour changes by itself
A26: Pair score difference needed | B26: 2 | C26: Base score minus quote score must be ≥ this for a LONG signal (≤ −this for SHORT). | E26: LONG | F26: Long / hawkish / supportive: LONG · HAWKISH · RISK-ON · ACTIVE · OK · BACKS THE CALL · STRONG · YES | G26: Bias, Compare, Scorecard, Risk & Gold, Hub, Journal
A27: 2Y differential confirmation (bp) | B27: 10 | C27: The 2Y yield spread must have moved ≥ this in the same direction over 1 month, otherwise FLAT. | E27: SHORT | F27: Short / dovish / against: SHORT · DOVISH · RISK-OFF · EXPIRED · STALE · AGAINST · WEAK · NO | G27: Bias, Compare, Scorecard, Risk & Gold, Hub, Journal
A28: VIX calm level | B28: 18 | C28: From investing Layer 3: VIX below this (and S&P above 200-day) = RISK-ON. | E28: NOT REVIEWED | F28: Needs attention: ENTER DATA · NOT REVIEWED · NOT CHECKED · CAUTION · MIXED · PARTLY · MODERATE · NEAR · yields NO | G28: Every sheet except Start Here
A29: VIX stress level | B29: 30 | C29: From investing Layer 3: VIX above this = RISK-OFF. | E29: FLAT | F29: No edge — stand aside: FLAT · NEUTRAL | G29: Bias, Compare, Scorecard, Risk & Gold, Hub, Journal
A30: Real-yield move for gold (bp) | B30: 15 | C30: US 10Y real yield down ≥ this over 1 month = +1 for gold; up ≥ this = −1. | E30: +1 | F30: Score above zero (green) — supports the currency / gold | G30: Scorecard, Risk & Gold
A31: Dollar move for gold (%) | B31: 1 | C31: Dollar index down ≥ this % over 1 month = +1 for gold; up ≥ this = −1. | E31: −1 | F31: Score below zero (red) — works against it | G31: Scorecard, Risk & Gold
A32: Gold score cut-off | B32: 2 | C32: Gold total ≥ +2 = LONG, ≤ −2 = SHORT. | E32: ■■■ | F32: Bar: green = base currency wins this factor | G32: Compare
A33: Key level 'near' distance (%) | B33: 0.5 | C33: Key Levels flags a level as NEAR when price is within this % of it. | E33: ■■■ | F33: Bar: red = quote currency wins this factor | G33: Compare
A34: Bias valid for (days) | B34: 7 | C34: After this many days without review the bias shows EXPIRED — treat as FLAT. | E34: KEY LEVEL TYPES
A35: Starting thresholds are Claude's suggestions, not tested values — tune them after journaling a few months. | E35: Policy line | F35: Government / central bank acted here | G35: Key Levels
E36: Options / GEX | F36: Big option strikes or expiries | G36: Key Levels
A37: FREE DATA SOURCES | E37: Structural | F37: Prior highs & lows, round numbers | G37: Key Levels
A38: US data (CPI, unemployment, 2Y, real yield, VIX, dollar) | B38: FRED (fred.stlouisfed.org): CPILFESL (core CPI, 'percent change from year ago'), UNRATE, DGS2, DFII10 (10Y real), VIXCLS, DTWEXBGS (broad dollar) | E38: Session | F38: Intraday: PDH/PDL, session ranges | G38: Key Levels
A39: EUR / GBP / JPY data | B39: tradingeconomics.com or investing.com economic calendar (core CPI, unemployment, composite PMI) | E39: 3 | F39: Strength 3 = strongest level (bold red) | G39: Key Levels
A40: 2Y government yields (all) | B40: investing.com → Bonds → country 2-year | E40: SHEET TABS
A41: S&P 500 and 200-day average | B41: TradingView chart (add 200 SMA) | E41: Navy tab | F41: Start here — guide, rules, legend | G41: Start Here
...

Sheet Bias
A1: Bias Board — Layer 1 permission | Q1: ← Start Here
A2: FINAL BIAS = what Layers 2–4 are allowed to trade. FLAT or EXPIRED = no macro permission.
A4: Pair | B4: Base | C4: Quote | D4: Base score | E4: Quote score | F4: Score diff | G4: 2Y spread now (bp) | H4: 2Y spread 1M ago (bp) | I4: Δ 2Y spread (bp) | J4: Macro signal | K4: Yields confirm? | L4: Risk override | M4: FINAL BIAS | N4: Last reviewed | O4: Valid until | P4: Status | Q4: Invalidation — what would flip it?
A5: EURUSD | B5: EUR | C5: USD | D5: =IFERROR(INDEX(Scorecard!$Q$5:$Q$12,MATCH(B5,Scorecard!$A$5:$A$12,0)),"") -> -1 | E5: =IFERROR(INDEX(Scorecard!$Q$5:$Q$12,MATCH(C5,Scorecard!$A$5:$A$12,0)),"") -> 3 | F5: =IF(OR(D5="",E5=""),"",D5-E5) -> -4 | G5: =IFERROR((INDEX(Scorecard!$K$5:$K$12,MATCH(B5,Scorecard!$A$5:$A$12,0))-INDEX(Scorecard!$K$5:$K$12,MATCH(C5,Scorecard!$A$5:$A$12,0)))*100,"") -> -210 | H5: =IFERROR((INDEX(Scorecard!$L$5:$L$12,MATCH(B5,Scorecard!$A$5:$A$12,0))-INDEX(Scorecard!$L$5:$L$12,MATCH(C5,Scorecard!$A$5:$A$12,0)))*100,"") -> -185 | I5: =IF(OR(G5="",H5=""),"",ROUND(G5-H5,1)) -> -25 | J5: =IF(F5="","",IF(F5>='Start Here'!$B$26,"LONG",IF(F5<=-'Start Here'!$B$26,"SHORT","FLAT"))) -> SHORT | K5: =IF(J5="LONG",IF(I5>='Start Here'!$B$27,"YES","NO"),IF(J5="SHORT",IF(I5<=-'Start Here'!$B$27,"YES","NO"),"—")) -> YES | L5: =IF(AND('Risk & Gold'!$B$8="RISK-OFF",OR(AND(C5="JPY",J5="LONG"),AND(B5="JPY",J5="SHORT"))),"YES: JPY haven","—") -> — | M5: =IF(F5="","ENTER DATA",IF(L5<>"—","FLAT",IF(K5="YES",J5,"FLAT"))) -> SHORT | N5: 46284 | O5: =IF(N5="","",N5+'Start Here'!$B$34) -> 46291 | P5: =IF(N5="","NOT REVIEWED",IF(TODAY()>O5,"EXPIRED","ACTIVE")) -> ACTIVE | Q5: EXAMPLE: FLAT until USD–EUR score gap reaches 2 and the 2Y spread confirms
A6: GBPUSD | B6: GBP | C6: USD | D6: =IFERROR(INDEX(Scorecard!$Q$5:$Q$12,MATCH(B6,Scorecard!$A$5:$A$12,0)),"") -> -1 | E6: =IFERROR(INDEX(Scorecard!$Q$5:$Q$12,MATCH(C6,Scorecard!$A$5:$A$12,0)),"") -> 3 | F6: =IF(OR(D6="",E6=""),"",D6-E6) -> -4 | G6: =IFERROR((INDEX(Scorecard!$K$5:$K$12,MATCH(B6,Scorecard!$A$5:$A$12,0))-INDEX(Scorecard!$K$5:$K$12,MATCH(C6,Scorecard!$A$5:$A$12,0)))*100,"") -> -30 | H6: =IFERROR((INDEX(Scorecard!$L$5:$L$12,MATCH(B6,Scorecard!$A$5:$A$12,0))-INDEX(Scorecard!$L$5:$L$12,MATCH(C6,Scorecard!$A$5:$A$12,0)))*100,"") -> 0 | I6: =IF(OR(G6="",H6=""),"",ROUND(G6-H6,1)) -> -30 | J6: =IF(F6="","",IF(F6>='Start Here'!$B$26,"LONG",IF(F6<=-'Start Here'!$B$26,"SHORT","FLAT"))) -> SHORT | K6: =IF(J6="LONG",IF(I6>='Start Here'!$B$27,"YES","NO"),IF(J6="SHORT",IF(I6<=-'Start Here'!$B$27,"YES","NO"),"—")) -> YES | L6: =IF(AND('Risk & Gold'!$B$8="RISK-OFF",OR(AND(C6="JPY",J6="LONG"),AND(B6="JPY",J6="SHORT"))),"YES: JPY haven","—") -> — | M6: =IF(F6="","ENTER DATA",IF(L6<>"—","FLAT",IF(K6="YES",J6,"FLAT"))) -> SHORT | O6: =IF(N6="","",N6+'Start Here'!$B$34) | P6: =IF(N6="","NOT REVIEWED",IF(TODAY()>O6,"EXPIRED","ACTIVE")) -> NOT REVIEWED
A7: USDJPY | B7: USD | C7: JPY | D7: =IFERROR(INDEX(Scorecard!$Q$5:$Q$12,MATCH(B7,Scorecard!$A$5:$A$12,0)),"") -> 3 | E7: =IFERROR(INDEX(Scorecard!$Q$5:$Q$12,MATCH(C7,Scorecard!$A$5:$A$12,0)),"") -> 1 | F7: =IF(OR(D7="",E7=""),"",D7-E7) -> 2 | G7: =IFERROR((INDEX(Scorecard!$K$5:$K$12,MATCH(B7,Scorecard!$A$5:$A$12,0))-INDEX(Scorecard!$K$5:$K$12,MATCH(C7,Scorecard!$A$5:$A$12,0)))*100,"") -> 310 | H7: =IFERROR((INDEX(Scorecard!$L$5:$L$12,MATCH(B7,Scorecard!$A$5:$A$12,0))-INDEX(Scorecard!$L$5:$L$12,MATCH(C7,Scorecard!$A$5:$A$12,0)))*100,"") -> 300 | I7: =IF(OR(G7="",H7=""),"",ROUND(G7-H7,1)) -> 10 | J7: =IF(F7="","",IF(F7>='Start Here'!$B$26,"LONG",IF(F7<=-'Start Here'!$B$26,"SHORT","FLAT"))) -> LONG | K7: =IF(J7="LONG",IF(I7>='Start Here'!$B$27,"YES","NO"),IF(J7="SHORT",IF(I7<=-'Start Here'!$B$27,"YES","NO"),"—")) -> YES | L7: =IF(AND('Risk & Gold'!$B$8="RISK-OFF",OR(AND(C7="JPY",J7="LONG"),AND(B7="JPY",J7="SHORT"))),"YES: JPY haven","—") -> — | M7: =IF(F7="","ENTER DATA",IF(L7<>"—","FLAT",IF(K7="YES",J7,"FLAT"))) -> LONG | O7: =IF(N7="","",N7+'Start Here'!$B$34) | P7: =IF(N7="","NOT REVIEWED",IF(TODAY()>O7,"EXPIRED","ACTIVE")) -> NOT REVIEWED
A8: XAUUSD | B8: XAU | C8: USD | D8: — | E8: — | F8: ='Risk & Gold'!E17 -> 0 | G8: — | H8: — | I8: — | J8: ='Risk & Gold'!B18 -> FLAT | K8: — | L8: — | M8: ='Risk & Gold'!B18 -> FLAT | N8: 46284 | O8: =IF(N8="","",N8+'Start Here'!$B$34) -> 46291 | P8: =IF(N8="","NOT REVIEWED",IF(TODAY()>O8,"EXPIRED","ACTIVE")) -> ACTIVE | Q8: Turns LONG if real yields fall ≥15 bp or dollar drops ≥1% (research stays +1). Turns SHORT if dollar rises ≥1% AND research drops to 0.
A10: HOW FINAL BIAS IS DECIDED
A11: 1. Score diff (base − quote) ≥ +2 → LONG signal, ≤ −2 → SHORT signal, else FLAT.
A12: 2. The 2Y yield spread must have moved the same way over the last month (≥ 10 bp), otherwise FLAT — the market has to confirm your thesis.
A13: 3. In RISK-OFF, any trade against JPY is overridden to FLAT.
A14: 4. Gold comes from the Risk & Gold sheet.
A15: 5. Unreviewed for 7+ days = EXPIRED = treat as FLAT.

Sheet Compare
A1: Pair Compare — side by side | L1: ← Start Here
A2: Pick any two currencies from the Scorecard. Every factor shows who wins and whether it backs the call.
K3: PICK THE PAIR
A4: Factor | B4: =L4 -> USD | C4: ◀ base | D4: quote ▶ | E4: =L5 -> GBP | F4: Gap (base − quote) | G4: Winner | H4: Backs the call? | I4: What it measures | K4: Base currency | L4: USD
A5: Inflation score (−1…+1) | B5: =IFERROR(IF(INDEX(Scorecard!$M$5:$M$12,MATCH($L$4,Scorecard!$A$5:$A$12,0))="","",INDEX(Scorecard!$M$5:$M$12,MATCH($L$4,Scorecard!$A$5:$A$12,0))),"") -> 1 | C5: =IF(F5="","",REPT("■",MIN(6,ROUND(MAX(0,F5)*1,0)))) -> ■ | D5: =IF(F5="","",REPT("■",MIN(6,ROUND(MAX(0,-F5)*1,0)))) | E5: =IFERROR(IF(INDEX(Scorecard!$M$5:$M$12,MATCH($L$5,Scorecard!$A$5:$A$12,0))="","",INDEX(Scorecard!$M$5:$M$12,MATCH($L$5,Scorecard!$A$5:$A$12,0))),"") -> 0 | F5: =IF(OR(B5="",E5=""),"",B5-E5) -> 1 | G5: =IF(F5="","",IF(ABS(F5)<0.1,"LEVEL",IF(F5>0,$L$4,$L$5))) -> USD | H5: =IF(OR(G5="",G5="LEVEL",$L$9=""),"—",IF(G5=$L$9,"BACKS THE CALL","AGAINST")) -> BACKS THE CALL | I5: Core CPI vs target and direction | K5: Quote currency | L5: GBP
A6: Labour score (−1…+1) | B6: =IFERROR(IF(INDEX(Scorecard!$N$5:$N$12,MATCH($L$4,Scorecard!$A$5:$A$12,0))="","",INDEX(Scorecard!$N$5:$N$12,MATCH($L$4,Scorecard!$A$5:$A$12,0))),"") -> 0 | C6: =IF(F6="","",REPT("■",MIN(6,ROUND(MAX(0,F6)*1,0)))) -> ■ | D6: =IF(F6="","",REPT("■",MIN(6,ROUND(MAX(0,-F6)*1,0)))) | E6: =IFERROR(IF(INDEX(Scorecard!$N$5:$N$12,MATCH($L$5,Scorecard!$A$5:$A$12,0))="","",INDEX(Scorecard!$N$5:$N$12,MATCH($L$5,Scorecard!$A$5:$A$12,0))),"") -> -1 | F6: =IF(OR(B6="",E6=""),"",B6-E6) -> 1 | G6: =IF(F6="","",IF(ABS(F6)<0.1,"LEVEL",IF(F6>0,$L$4,$L$5))) -> USD | H6: =IF(OR(G6="",G6="LEVEL",$L$9=""),"—",IF(G6=$L$9,"BACKS THE CALL","AGAINST")) -> BACKS THE CALL | I6: 3-month change in unemployment | K6: Pair | L6: =L4&L5 -> USDGBP
A7: Growth score (−1…+1) | B7: =IFERROR(IF(INDEX(Scorecard!$O$5:$O$12,MATCH($L$4,Scorecard!$A$5:$A$12,0))="","",INDEX(Scorecard!$O$5:$O$12,MATCH($L$4,Scorecard!$A$5:$A$12,0))),"") -> 1 | C7: =IF(F7="","",REPT("■",MIN(6,ROUND(MAX(0,F7)*1,0)))) -> ■ | D7: =IF(F7="","",REPT("■",MIN(6,ROUND(MAX(0,-F7)*1,0)))) | E7: =IFERROR(IF(INDEX(Scorecard!$O$5:$O$12,MATCH($L$5,Scorecard!$A$5:$A$12,0))="","",INDEX(Scorecard!$O$5:$O$12,MATCH($L$5,Scorecard!$A$5:$A$12,0))),"") -> 0 | F7: =IF(OR(B7="",E7=""),"",B7-E7) -> 1 | G7: =IF(F7="","",IF(ABS(F7)<0.1,"LEVEL",IF(F7>0,$L$4,$L$5))) -> USD | H7: =IF(OR(G7="",G7="LEVEL",$L$9=""),"—",IF(G7=$L$9,"BACKS THE CALL","AGAINST")) -> BACKS THE CALL | I7: Composite PMI | K7: Direction from scores | L7: =IFERROR(IF(OR(INDEX(Scorecard!$Q$5:$Q$12,MATCH($L$4,Scorecard!$A$5:$A$12,0))="",INDEX(Scorecard!$Q$5:$Q$12,MATCH($L$5,Scorecard!$A$5:$A$12,0))=""),"ENTER DATA",IF(INDEX(Scorecard!$Q$5:$Q$12,MATCH($L$4,Scorecard!$A$5:$A$12,0))-INDEX(Scorecard!$Q$5:$Q$12,MATCH($L$5,Scorecard!$A$5:$A$12,0))>='Start Here'!$B$26,"LONG",IF(INDEX(Scorecard!$Q$5:$Q$12,MATCH($L$4,Scorecard!$A$5:$A$12,0))-INDEX(Scorecard!$Q$5:$Q$12,MATCH($L$5,Scorecard!$A$5:$A$12,0))<=-'Start Here'!$B$26,"SHORT","FLAT"))),"PICK CURRENCIES") -> LONG
A8: Pricing score (−1…+1) | B8: =IFERROR(IF(INDEX(Scorecard!$P$5:$P$12,MATCH($L$4,Scorecard!$A$5:$A$12,0))="","",INDEX(Scorecard!$P$5:$P$12,MATCH($L$4,Scorecard!$A$5:$A$12,0))),"") -> 1 | C8: =IF(F8="","",REPT("■",MIN(6,ROUND(MAX(0,F8)*1,0)))) -> ■ | D8: =IF(F8="","",REPT("■",MIN(6,ROUND(MAX(0,-F8)*1,0)))) | E8: =IFERROR(IF(INDEX(Scorecard!$P$5:$P$12,MATCH($L$5,Scorecard!$A$5:$A$12,0))="","",INDEX(Scorecard!$P$5:$P$12,MATCH($L$5,Scorecard!$A$5:$A$12,0))),"") -> 0 | F8: =IF(OR(B8="",E8=""),"",B8-E8) -> 1 | G8: =IF(F8="","",IF(ABS(F8)<0.1,"LEVEL",IF(F8>0,$L$4,$L$5))) -> USD | H8: =IF(OR(G8="",G8="LEVEL",$L$9=""),"—",IF(G8=$L$9,"BACKS THE CALL","AGAINST")) -> BACKS THE CALL | I8: 1-month move in 2Y yield = market repricing | K8: Final bias on Bias board | L8: =IFERROR(INDEX(Bias!$M$5:$M$8,MATCH(L6,Bias!$A$5:$A$8,0)),"not on board") -> not on board
A9: 2Y yield (%) | B9: =IFERROR(IF(INDEX(Scorecard!$K$5:$K$12,MATCH($L$4,Scorecard!$A$5:$A$12,0))="","",INDEX(Scorecard!$K$5:$K$12,MATCH($L$4,Scorecard!$A$5:$A$12,0))),"") -> 4.1 | C9: =IF(F9="","",REPT("■",MIN(6,ROUND(MAX(0,F9)*2,0)))) -> ■ | D9: =IF(F9="","",REPT("■",MIN(6,ROUND(MAX(0,-F9)*2,0)))) | E9: =IFERROR(IF(INDEX(Scorecard!$K$5:$K$12,MATCH($L$5,Scorecard!$A$5:$A$12,0))="","",INDEX(Scorecard!$K$5:$K$12,MATCH($L$5,Scorecard!$A$5:$A$12,0))),"") -> 3.8 | F9: =IF(OR(B9="",E9=""),"",B9-E9) -> 0.3 | G9: =IF(F9="","",IF(ABS(F9)<0.1,"LEVEL",IF(F9>0,$L$4,$L$5))) -> USD | H9: =IF(OR(G9="",G9="LEVEL",$L$9=""),"—",IF(G9=$L$9,"BACKS THE CALL","AGAINST")) -> BACKS THE CALL | I9: Level — the carry edge | K9: Currency the call favours | L9: =IF(L7="LONG",L4,IF(L7="SHORT",L5,"")) -> USD
A10: Real 2Y yield (%) | B10: =IFERROR(IF(OR(INDEX(Scorecard!$K$5:$K$12,MATCH($L$4,Scorecard!$A$5:$A$12,0))="",INDEX(Scorecard!$E$5:$E$12,MATCH($L$4,Scorecard!$A$5:$A$12,0))=""),"",INDEX(Scorecard!$K$5:$K$12,MATCH($L$4,Scorecard!$A$5:$A$12,0))-INDEX(Scorecard!$E$5:$E$12,MATCH($L$4,Scorecard!$A$5:$A$12,0))),"") -> 1.1 | C10: =IF(F10="","",REPT("■",MIN(6,ROUND(MAX(0,F10)*2,0)))) -> ■ | D10: =IF(F10="","",REPT("■",MIN(6,ROUND(MAX(0,-F10)*2,0)))) | E10: =IFERROR(IF(OR(INDEX(Scorecard!$K$5:$K$12,MATCH($L$5,Scorecard!$A$5:$A$12,0))="",INDEX(Scorecard!$E$5:$E$12,MATCH($L$5,Scorecard!$A$5:$A$12,0))=""),"",INDEX(Scorecard!$K$5:$K$12,MATCH($L$5,Scorecard!$A$5:$A$12,0))-INDEX(Scorecard!$E$5:$E$12,MATCH($L$5,Scorecard!$A$5:$A$12,0))),"") -> 0.4 | F10: =IF(OR(B10="",E10=""),"",B10-E10) -> 0.7 | G10: =IF(F10="","",IF(ABS(F10)<0.1,"LEVEL",IF(F10>0,$L$4,$L$5))) -> USD | H10: =IF(OR(G10="",G10="LEVEL",$L$9=""),"—",IF(G10=$L$9,"BACKS THE CALL","AGAINST")) -> BACKS THE CALL | I10: 2Y yield minus core CPI — inflation-adjusted return
A11: Policy rate (%) | B11: =IFERROR(IF(INDEX(Scorecard!$C$5:$C$12,MATCH($L$4,Scorecard!$A$5:$A$12,0))="","",INDEX(Scorecard!$C$5:$C$12,MATCH($L$4,Scorecard!$A$5:$A$12,0))),"") -> 4 | C11: =IF(F11="","",REPT("■",MIN(6,ROUND(MAX(0,F11)*2,0)))) -> ■ | D11: =IF(F11="","",REPT("■",MIN(6,ROUND(MAX(0,-F11)*2,0)))) | E11: =IFERROR(IF(INDEX(Scorecard!$C$5:$C$12,MATCH($L$5,Scorecard!$A$5:$A$12,0))="","",INDEX(Scorecard!$C$5:$C$12,MATCH($L$5,Scorecard!$A$5:$A$12,0))),"") -> 3.75 | F11: =IF(OR(B11="",E11=""),"",B11-E11) -> 0.25 | G11: =IF(F11="","",IF(ABS(F11)<0.1,"LEVEL",IF(F11>0,$L$4,$L$5))) -> USD | H11: =IF(OR(G11="",G11="LEVEL",$L$9=""),"—",IF(G11=$L$9,"BACKS THE CALL","AGAINST")) -> BACKS THE CALL | I11: Where the central bank is now
A12: TOTAL SCORE | B12: =IFERROR(IF(INDEX(Scorecard!$Q$5:$Q$12,MATCH($L$4,Scorecard!$A$5:$A$12,0))="","",INDEX(Scorecard!$Q$5:$Q$12,MATCH($L$4,Scorecard!$A$5:$A$12,0))),"") -> 3 | E12: =IFERROR(IF(INDEX(Scorecard!$Q$5:$Q$12,MATCH($L$5,Scorecard!$A$5:$A$12,0))="","",INDEX(Scorecard!$Q$5:$Q$12,MATCH($L$5,Scorecard!$A$5:$A$12,0))),"") -> -1 | F12: =IF(OR(B12="",E12=""),"",B12-E12) -> 4
A14: DOES THE EVIDENCE BACK THE DIRECTION?
A15: Positive scores = hawkish pressure = supports that currency. Yield rows: 1 block ≈ 0.5 percentage point. Copy this sheet to keep several pairs open side by side.
A16: Scoreboard | B16: =L4&" wins "&COUNTIF(G5:G11,L4)&" of 7, "&L5&" wins "&COUNTIF(G5:G11,L5)&", level on "&COUNTIF(G5:G11,"LEVEL") -> USD wins 7 of 7, GBP wins 0, level on 0
A17: Verdict | B17: =IF(L9="","No directional call — use as comparison only",IF(COUNTIF(H5:H11,"BACKS THE CALL")>=5,"STRONG — evidence backs the call",IF(COUNTIF(H5:H11,"BACKS THE CALL")>COUNTIF(H5:H11,"AGAINST"),"MODERATE — more for than against","WEAK — evidence does not back the call"))) -> STRONG — evidence backs the call
A18: Strongest reason to own the base | B18: =IF(MAX(F5:F8)>0,INDEX(A5:A8,MATCH(MAX(F5:F8),F5:F8,0))&" (gap +"&MAX(F5:F8)&")","None in the four scores") -> Inflation score (−1…+1) (gap +1)
A19: Strongest reason to own the quote | B19: =IF(MIN(F5:F8)<0,INDEX(A5:A8,MATCH(MIN(F5:F8),F5:F8,0))&" (gap "&MIN(F5:F8)&")","None in the four scores") -> None in the four scores
A20: Your read — why lean this way? | B20: EXAMPLE: USD repricing hawkishly while ECB is on hold; spread widening in USD's favour
A21: What keeps conviction down? (price not confirming, crowded positioning, catalyst ahead) | B21: EXAMPLE: EUR/USD not breaking structure yet; CPI next week

Sheet Scorecard
A1: Currency Scorecard | S1: ← Start Here
A2: ⚠ EXAMPLE VALUES — illustrative only, not current data. Replace every blue cell before use.
A3: Each currency scores −1 / 0 / +1 on four drivers. Positive = hawkish pressure (supports the currency).
A4: Currency | B4: Central bank | C4: Policy rate (%) | D4: Next meeting | E4: Core CPI YoY (%) | F4: Core CPI 3M ago (%) | G4: Inflation target (%) | H4: Unemployment (%) | I4: Unemployment 3M ago (%) | J4: Composite PMI | K4: 2Y yield (%) | L4: 2Y yield 1M ago (%) | M4: Inflation score | N4: Labour score | O4: Growth score | P4: Pricing score (2Y) | Q4: TOTAL | R4: STANCE | S4: Notes — what would change it?
A5: USD | B5: Fed | C5: 4 | E5: 3 | F5: 2.8 | G5: 2 | H5: 4.3 | I5: 4.2 | J5: 52.5 | K5: 4.1 | L5: 3.9 | M5: =IF(COUNT(E5,F5,G5)<3,"",IF(AND(E5>G5,E5>=F5),1,IF(AND(E5<F5,E5<=G5+'Start Here'!$B$20),-1,0))) -> 1 | N5: =IF(COUNT(H5,I5)<2,"",IF(H5-I5<=-'Start Here'!$B$21,1,IF(H5-I5>='Start Here'!$B$21,-1,0))) -> 0 | O5: =IF(J5="","",IF(J5>='Start Here'!$B$22,1,IF(J5<='Start Here'!$B$23,-1,0))) -> 1 | P5: =IF(COUNT(K5,L5)<2,"",IF((K5-L5)*100>='Start Here'!$B$24,1,IF((K5-L5)*100<=-'Start Here'!$B$24,-1,0))) -> 1 | Q5: =IF(COUNT(M5:P5)<4,"",SUM(M5:P5)) -> 3 | R5: =IF(Q5="","ENTER DATA",IF(Q5>='Start Here'!$B$25,"HAWKISH",IF(Q5<=-'Start Here'!$B$25,"DOVISH","NEUTRAL"))) -> HAWKISH | S5: EXAMPLE: services inflation re-accelerating; a soft CPI print would flip inflation score to 0
A6: EUR | B6: ECB | C6: 2 | E6: 2.1 | F6: 2.3 | G6: 2 | H6: 6.3 | I6: 6.3 | J6: 50.2 | K6: 2 | L6: 2.05 | M6: =IF(COUNT(E6,F6,G6)<3,"",IF(AND(E6>G6,E6>=F6),1,IF(AND(E6<F6,E6<=G6+'Start Here'!$B$20),-1,0))) -> -1 | N6: =IF(COUNT(H6,I6)<2,"",IF(H6-I6<=-'Start Here'!$B$21,1,IF(H6-I6>='Start Here'!$B$21,-1,0))) -> 0 | O6: =IF(J6="","",IF(J6>='Start Here'!$B$22,1,IF(J6<='Start Here'!$B$23,-1,0))) -> 0 | P6: =IF(COUNT(K6,L6)<2,"",IF((K6-L6)*100>='Start Here'!$B$24,1,IF((K6-L6)*100<=-'Start Here'!$B$24,-1,0))) -> 0 | Q6: =IF(COUNT(M6:P6)<4,"",SUM(M6:P6)) -> -1 | R6: =IF(Q6="","ENTER DATA",IF(Q6>='Start Here'!$B$25,"HAWKISH",IF(Q6<=-'Start Here'!$B$25,"DOVISH","NEUTRAL"))) -> NEUTRAL
A7: GBP | B7: BoE | C7: 3.75 | E7: 3.4 | F7: 3.5 | G7: 2 | H7: 4.9 | I7: 4.6 | J7: 50.8 | K7: 3.8 | L7: 3.9 | M7: =IF(COUNT(E7,F7,G7)<3,"",IF(AND(E7>G7,E7>=F7),1,IF(AND(E7<F7,E7<=G7+'Start Here'!$B$20),-1,0))) -> 0 | N7: =IF(COUNT(H7,I7)<2,"",IF(H7-I7<=-'Start Here'!$B$21,1,IF(H7-I7>='Start Here'!$B$21,-1,0))) -> -1 | O7: =IF(J7="","",IF(J7>='Start Here'!$B$22,1,IF(J7<='Start Here'!$B$23,-1,0))) -> 0 | P7: =IF(COUNT(K7,L7)<2,"",IF((K7-L7)*100>='Start Here'!$B$24,1,IF((K7-L7)*100<=-'Start Here'!$B$24,-1,0))) -> 0 | Q7: =IF(COUNT(M7:P7)<4,"",SUM(M7:P7)) -> -1 | R7: =IF(Q7="","ENTER DATA",IF(Q7>='Start Here'!$B$25,"HAWKISH",IF(Q7<=-'Start Here'!$B$25,"DOVISH","NEUTRAL"))) -> NEUTRAL
A8: JPY | B8: BoJ | C8: 1 | E8: 2.2 | F8: 2 | G8: 2 | H8: 2.5 | I8: 2.5 | J8: 51 | K8: 1 | L8: 0.9 | M8: =IF(COUNT(E8,F8,G8)<3,"",IF(AND(E8>G8,E8>=F8),1,IF(AND(E8<F8,E8<=G8+'Start Here'!$B$20),-1,0))) -> 1 | N8: =IF(COUNT(H8,I8)<2,"",IF(H8-I8<=-'Start Here'!$B$21,1,IF(H8-I8>='Start Here'!$B$21,-1,0))) -> 0 | O8: =IF(J8="","",IF(J8>='Start Here'!$B$22,1,IF(J8<='Start Here'!$B$23,-1,0))) -> 0 | P8: =IF(COUNT(K8,L8)<2,"",IF((K8-L8)*100>='Start Here'!$B$24,1,IF((K8-L8)*100<=-'Start Here'!$B$24,-1,0))) -> 0 | Q8: =IF(COUNT(M8:P8)<4,"",SUM(M8:P8)) -> 1 | R8: =IF(Q8="","ENTER DATA",IF(Q8>='Start Here'!$B$25,"HAWKISH",IF(Q8<=-'Start Here'!$B$25,"DOVISH","NEUTRAL"))) -> NEUTRAL
A9: AUD | B9: RBA | G9: 2.5 | M9: =IF(COUNT(E9,F9,G9)<3,"",IF(AND(E9>G9,E9>=F9),1,IF(AND(E9<F9,E9<=G9+'Start Here'!$B$20),-1,0))) | N9: =IF(COUNT(H9,I9)<2,"",IF(H9-I9<=-'Start Here'!$B$21,1,IF(H9-I9>='Start Here'!$B$21,-1,0))) | O9: =IF(J9="","",IF(J9>='Start Here'!$B$22,1,IF(J9<='Start Here'!$B$23,-1,0))) | P9: =IF(COUNT(K9,L9)<2,"",IF((K9-L9)*100>='Start Here'!$B$24,1,IF((K9-L9)*100<=-'Start Here'!$B$24,-1,0))) | Q9: =IF(COUNT(M9:P9)<4,"",SUM(M9:P9)) | R9: =IF(Q9="","ENTER DATA",IF(Q9>='Start Here'!$B$25,"HAWKISH",IF(Q9<=-'Start Here'!$B$25,"DOVISH","NEUTRAL"))) -> ENTER DATA
A10: NZD | B10: RBNZ | G10: 2 | M10: =IF(COUNT(E10,F10,G10)<3,"",IF(AND(E10>G10,E10>=F10),1,IF(AND(E10<F10,E10<=G10+'Start Here'!$B$20),-1,0))) | N10: =IF(COUNT(H10,I10)<2,"",IF(H10-I10<=-'Start Here'!$B$21,1,IF(H10-I10>='Start Here'!$B$21,-1,0))) | O10: =IF(J10="","",IF(J10>='Start Here'!$B$22,1,IF(J10<='Start Here'!$B$23,-1,0))) | P10: =IF(COUNT(K10,L10)<2,"",IF((K10-L10)*100>='Start Here'!$B$24,1,IF((K10-L10)*100<=-'Start Here'!$B$24,-1,0))) | Q10: =IF(COUNT(M10:P10)<4,"",SUM(M10:P10)) | R10: =IF(Q10="","ENTER DATA",IF(Q10>='Start Here'!$B$25,"HAWKISH",IF(Q10<=-'Start Here'!$B$25,"DOVISH","NEUTRAL"))) -> ENTER DATA
A11: CAD | B11: BoC | G11: 2 | M11: =IF(COUNT(E11,F11,G11)<3,"",IF(AND(E11>G11,E11>=F11),1,IF(AND(E11<F11,E11<=G11+'Start Here'!$B$20),-1,0))) | N11: =IF(COUNT(H11,I11)<2,"",IF(H11-I11<=-'Start Here'!$B$21,1,IF(H11-I11>='Start Here'!$B$21,-1,0))) | O11: =IF(J11="","",IF(J11>='Start Here'!$B$22,1,IF(J11<='Start Here'!$B$23,-1,0))) | P11: =IF(COUNT(K11,L11)<2,"",IF((K11-L11)*100>='Start Here'!$B$24,1,IF((K11-L11)*100<=-'Start Here'!$B$24,-1,0))) | Q11: =IF(COUNT(M11:P11)<4,"",SUM(M11:P11)) | R11: =IF(Q11="","ENTER DATA",IF(Q11>='Start Here'!$B$25,"HAWKISH",IF(Q11<=-'Start Here'!$B$25,"DOVISH","NEUTRAL"))) -> ENTER DATA
A12: CHF | B12: SNB | G12: 1 | M12: =IF(COUNT(E12,F12,G12)<3,"",IF(AND(E12>G12,E12>=F12),1,IF(AND(E12<F12,E12<=G12+'Start Here'!$B$20),-1,0))) | N12: =IF(COUNT(H12,I12)<2,"",IF(H12-I12<=-'Start Here'!$B$21,1,IF(H12-I12>='Start Here'!$B$21,-1,0))) | O12: =IF(J12="","",IF(J12>='Start Here'!$B$22,1,IF(J12<='Start Here'!$B$23,-1,0))) | P12: =IF(COUNT(K12,L12)<2,"",IF((K12-L12)*100>='Start Here'!$B$24,1,IF((K12-L12)*100<=-'Start Here'!$B$24,-1,0))) | Q12: =IF(COUNT(M12:P12)<4,"",SUM(M12:P12)) | R12: =IF(Q12="","ENTER DATA",IF(Q12>='Start Here'!$B$25,"HAWKISH",IF(Q12<=-'Start Here'!$B$25,"DOVISH","NEUTRAL"))) -> ENTER DATA
A14: AUD, NZD, CAD, CHF are ready but empty — fill them only when you start trading those pairs. Targets: RBA 2–3% band, RBNZ 1–3% band and SNB 0–2% band use the midpoint.

Sheet Risk & Gold
A1: Risk Regime & Gold | F1: ← Start Here
A2: LIVE DATA as of 18–19 Sep 2026 (Claude, from the sources in the Notes column). Re-check weekly.
A4: RISK REGIME (borrowed from your investing Layer 3 VIX rules)
A5: VIX | B5: 14.81 | C5: VIX < calm level (Start Here) and S&P above its 200-day = RISK-ON
A6: S&P 500 close | B6: 7650.5 | C6: VIX > stress level = RISK-OFF
A7: S&P 500 200-day average | B7: 7183.05 | C7: Anything in between = CAUTION
A8: REGIME | B8: =IF(COUNT(B5:B7)<3,"ENTER DATA",IF(B5>'Start Here'!$B$29,"RISK-OFF",IF(OR(B5>='Start Here'!$B$28,B6<B7),"CAUTION","RISK-ON"))) -> RISK-ON | C8: RISK-OFF: no trades against JPY/safe havens · CAUTION: size down / A+ only · RISK-ON: normal
A11: GOLD DRIVERS
A12: Driver | B12: Now | C12: 1 month ago | D12: Change | E12: Score | F12: Notes
A13: US 10Y real yield (%) — FRED DFII10 | B13: 2.66 | C13: 2.4 | D13: =IF(COUNT(B13:C13)<2,"",(B13-C13)*100) -> 26 | E13: =IF(D13="","",IF(D13<=-'Start Here'!$B$30,1,IF(D13>='Start Here'!$B$30,-1,0))) -> -1 | F13: Now: 10Y TIPS 2.66% on 18 Sep (StreetStats); Sep 17 auction at 2.653%, highest since 2008 (Tipswatch). 1M ago ≈2.39–2.40% (Convex/FRED). Rising real yields = headwind.
A14: Dollar index — ICE DXY (use the SAME series for both cells) | B14: 100.22 | C14: 99.65 | D14: =IF(COUNT(B14:C14)<2,"",(B14/C14-1)*100) -> 0.57200201 | E14: =IF(D14="","",IF(D14<=-'Start Here'!$B$31,1,IF(D14>='Start Here'!$B$31,-1,0))) -> 0 | F14: Now ≈100.2 near 7-week high after Fed hike (Trading Economics). 1M change +0.57% (Investing.com 19 Aug–19 Sep). +1.3% this week alone — watch.
A15: Risk regime | B15: =B8 -> RISK-ON | E15: =IF(B15="RISK-OFF",1,0) -> 0 | F15: Risk-off adds safe-haven demand
A16: Your research (CB buying, geopolitics, ETF flows) | B16: 1 | E16: =B16 -> 1 | F16: +1: CB buying 244t in Q1 (WGC); strong ETF inflows in Aug (WGC); Hormuz/Saudi supply risk. Risk to this: Fed signalled more hikes, Oct hike partly priced.
A17: GOLD TOTAL | E17: =IF(COUNT(E13:E16)<4,"",SUM(E13:E16)) -> 0
A18: GOLD BIAS | B18: =IF(E17="","ENTER DATA",IF(E17>='Start Here'!$B$32,"LONG",IF(E17<=-'Start Here'!$B$32,"SHORT","FLAT"))) -> FLAT

Sheet Key Levels
A1: Key Levels — where big players have shown their hand | L1: ← Start Here
A2: ⚠ Levels marked 'verify' come from memory or an older note — check them on the chart before relying on them.
A4: CURRENT PRICES (update weekly) | E4: HOW EACH TYPE BEHAVES
A5: Instrument | B5: Price | C5: Updated | E5: Type | F5: How it behaves
A6: USDJPY | B6: 157 | C6: 46283 | E6: Policy line | F6: A government/central bank acted here. Don't hold positions into it; they react to SPEED of the move, not just the number. Caps a trend, rarely reverses it.
A7: XAUUSD | B7: 4400 | C7: 46283 | E7: Options / GEX | F7: Big strikes or expiries. Pin price near expiry (positive gamma) or accelerate moves (negative gamma). Only valid until the expiry date.
A8: EURUSD | E8: Structural | F8: Prior-year/all-time highs & lows, round numbers. Stops cluster here → expect a sweep; trade the rejection, not the break.
A9: GBPUSD | E9: Session | F9: PDH/PDL, Asia/London range. Intraday only — refresh daily.
A10: NAS100
A12: Instrument | B12: Level | C12: Zone other edge | D12: Type | E12: Strength (1–3) | F12: What happened here | G12: Source | H12: Date set | I12: Last tested | J12: Reaction when tested | K12: Distance (%) | L12: Status
A13: USDJPY | B13: 164 | C13: 163 | D13: Policy line | E13: 3 | F13: Japan (joined by the US) bought yen after USD/JPY crossed 163 and neared 164 | G13: CNBC / Wikipedia, Aug 2026 | H13: 46234 | J13: Fell to ~155 within days | K13: =IF(OR(A13="",B13=""),"",IFERROR(IF(INDEX($B$6:$B$10,MATCH(A13,$A$6:$A$10,0))="","",(B13/INDEX($B$6:$B$10,MATCH(A13,$A$6:$A$10,0))-1)*100),"")) -> 4.4585987 | L13: =IF(K13="","",IF(ABS(K13)<='Start Here'!$B$33,"NEAR — watch",IF(K13>0,"above price","below price"))) -> above price
A14: USDJPY | B14: 161.95 | D14: Policy line | E14: 2 | F14: July 2024 high, intervention followed | G14: Claude from memory — verify | H14: 45484 | K14: =IF(OR(A14="",B14=""),"",IFERROR(IF(INDEX($B$6:$B$10,MATCH(A14,$A$6:$A$10,0))="","",(B14/INDEX($B$6:$B$10,MATCH(A14,$A$6:$A$10,0))-1)*100),"")) -> 3.1528662 | L14: =IF(K14="","",IF(ABS(K14)<='Start Here'!$B$33,"NEAR — watch",IF(K14>0,"above price","below price"))) -> above price
A15: USDJPY | B15: 160.2 | D15: Policy line | E15: 2 | F15: April 2024 high, intervention followed | G15: Claude from memory — verify | H15: 45411 | K15: =IF(OR(A15="",B15=""),"",IFERROR(IF(INDEX($B$6:$B$10,MATCH(A15,$A$6:$A$10,0))="","",(B15/INDEX($B$6:$B$10,MATCH(A15,$A$6:$A$10,0))-1)*100),"")) -> 2.0382166 | L15: =IF(K15="","",IF(ABS(K15)<='Start Here'!$B$33,"NEAR — watch",IF(K15>0,"above price","below price"))) -> above price
A16: USDJPY | B16: 160 | D16: Policy line | E16: 3 | F16: Widely cited political 'line in the sand'; MoF calls moves toward 160 disorderly | G16: OMFIF / CNBC, Aug 2026 | K16: =IF(OR(A16="",B16=""),"",IFERROR(IF(INDEX($B$6:$B$10,MATCH(A16,$A$6:$A$10,0))="","",(B16/INDEX($B$6:$B$10,MATCH(A16,$A$6:$A$10,0))-1)*100),"")) -> 1.910828 | L16: =IF(K16="","",IF(ABS(K16)<='Start Here'!$B$33,"NEAR — watch",IF(K16>0,"above price","below price"))) -> above price
A17: USDJPY | B17: 155.3 | D17: Structural | E17: 2 | F17: Post-intervention low; retested early September | G17: CNBC, Sep 2026 | H17: 46237 | I17: 46268 | J17: Held (~155.28) | K17: =IF(OR(A17="",B17=""),"",IFERROR(IF(INDEX($B$6:$B$10,MATCH(A17,$A$6:$A$10,0))="","",(B17/INDEX($B$6:$B$10,MATCH(A17,$A$6:$A$10,0))-1)*100),"")) -> -1.0828025 | L17: =IF(K17="","",IF(ABS(K17)<='Start Here'!$B$33,"NEAR — watch",IF(K17>0,"above price","below price"))) -> below price
A18: USDJPY | B18: 151.95 | D18: Policy line | E18: 1 | F18: October 2022 intervention high | G18: Claude from memory — verify | H18: 44855 | K18: =IF(OR(A18="",B18=""),"",IFERROR(IF(INDEX($B$6:$B$10,MATCH(A18,$A$6:$A$10,0))="","",(B18/INDEX($B$6:$B$10,MATCH(A18,$A$6:$A$10,0))-1)*100),"")) -> -3.2165605 | L18: =IF(K18="","",IF(ABS(K18)<='Start Here'!$B$33,"NEAR — watch",IF(K18>0,"above price","below price"))) -> below price
A19: USDJPY | B19: 145.9 | D19: Policy line | E19: 1 | F19: September 2022 first intervention | G19: Claude from memory — verify | H19: 44826 | K19: =IF(OR(A19="",B19=""),"",IFERROR(IF(INDEX($B$6:$B$10,MATCH(A19,$A$6:$A$10,0))="","",(B19/INDEX($B$6:$B$10,MATCH(A19,$A$6:$A$10,0))-1)*100),"")) -> -7.0700637 | L19: =IF(K19="","",IF(ABS(K19)<='Start Here'!$B$33,"NEAR — watch",IF(K19>0,"above price","below price"))) -> below price
A20: XAUUSD | B20: 5602 | D20: Structural | E20: 3 | F20: All-time high | G20: Your context doc (Jul 2026) — verify | H20: 46051 | K20: =IF(OR(A20="",B20=""),"",IFERROR(IF(INDEX($B$6:$B$10,MATCH(A20,$A$6:$A$10,0))="","",(B20/INDEX($B$6:$B$10,MATCH(A20,$A$6:$A$10,0))-1)*100),"")) -> 27.318182 | L20: =IF(K20="","",IF(ABS(K20)<='Start Here'!$B$33,"NEAR — watch",IF(K20>0,"above price","below price"))) -> above price
A21: XAUUSD | B21: 4563 | D21: Structural | E21: 2 | F21: End-of-August close after a 13% monthly rally — September has pulled back from here | G21: World Gold Council, Aug 2026 commentary | H21: 46265 | K21: =IF(OR(A21="",B21=""),"",IFERROR(IF(INDEX($B$6:$B$10,MATCH(A21,$A$6:$A$10,0))="","",(B21/INDEX($B$6:$B$10,MATCH(A21,$A$6:$A$10,0))-1)*100),"")) -> 3.7045455 | L21: =IF(K21="","",IF(ABS(K21)<='Start Here'!$B$33,"NEAR — watch",IF(K21>0,"above price","below price"))) -> above price
A22: XAUUSD | B22: 4439.8 | D22: Structural | E22: 1 | F22: Weekly high, broke above 4,400 after the Fed hike | G22: Yahoo Finance, 18 Sep 2026 | H22: 46283 | K22: =IF(OR(A22="",B22=""),"",IFERROR(IF(INDEX($B$6:$B$10,MATCH(A22,$A$6:$A$10,0))="","",(B22/INDEX($B$6:$B$10,MATCH(A22,$A$6:$A$10,0))-1)*100),"")) -> 0.90454545 | L22: =IF(K22="","",IF(ABS(K22)<='Start Here'!$B$33,"NEAR — watch",IF(K22>0,"above price","below price"))) -> above price
A23: XAUUSD | B23: 4261 | D23: Structural | E23: 2 | F23: Support zone at the near six-week low on Fed day (16 Sep) | G23: FX Leaders / Trading Economics, Sep 2026 | H23: 46281 | I23: 46281 | J23: Held — rebounded ~2% next day | K23: =IF(OR(A23="",B23=""),"",IFERROR(IF(INDEX($B$6:$B$10,MATCH(A23,$A$6:$A$10,0))="","",(B23/INDEX($B$6:$B$10,MATCH(A23,$A$6:$A$10,0))-1)*100),"")) -> -3.1590909 | L23: =IF(K23="","",IF(ABS(K23)<='Start Here'!$B$33,"NEAR — watch",IF(K23>0,"above price","below price"))) -> below price
A24: XAUUSD | B24: 4000 | C24: 4065 | D24: Structural | E24: 2 | F24: Range floor attributed to central-bank buying (as of July) | G24: Your context doc (Jul 2026) — re-verify, may be stale | K24: =IF(OR(A24="",B24=""),"",IFERROR(IF(INDEX($B$6:$B$10,MATCH(A24,$A$6:$A$10,0))="","",(B24/INDEX($B$6:$B$10,MATCH(A24,$A$6:$A$10,0))-1)*100),"")) -> -9.0909091 | L24: =IF(K24="","",IF(ABS(K24)<='Start Here'!$B$33,"NEAR — watch",IF(K24>0,"above price","below price"))) -> below price
K25: =IF(OR(A25="",B25=""),"",IFERROR(IF(INDEX($B$6:$B$10,MATCH(A25,$A$6:$A$10,0))="","",(B25/INDEX($B$6:$B$10,MATCH(A25,$A$6:$A$10,0))-1)*100),"")) | L25: =IF(K25="","",IF(ABS(K25)<='Start Here'!$B$33,"NEAR — watch",IF(K25>0,"above price","below price")))
K26: =IF(OR(A26="",B26=""),"",IFERROR(IF(INDEX($B$6:$B$10,MATCH(A26,$A$6:$A$10,0))="","",(B26/INDEX($B$6:$B$10,MATCH(A26,$A$6:$A$10,0))-1)*100),"")) | L26: =IF(K26="","",IF(ABS(K26)<='Start Here'!$B$33,"NEAR — watch",IF(K26>0,"above price","below price")))
K27: =IF(OR(A27="",B27=""),"",IFERROR(IF(INDEX($B$6:$B$10,MATCH(A27,$A$6:$A$10,0))="","",(B27/INDEX($B$6:$B$10,MATCH(A27,$A$6:$A$10,0))-1)*100),"")) | L27: =IF(K27="","",IF(ABS(K27)<='Start Here'!$B$33,"NEAR — watch",IF(K27>0,"above price","below price")))
K28: =IF(OR(A28="",B28=""),"",IFERROR(IF(INDEX($B$6:$B$10,MATCH(A28,$A$6:$A$10,0))="","",(B28/INDEX($B$6:$B$10,MATCH(A28,$A$6:$A$10,0))-1)*100),"")) | L28: =IF(K28="","",IF(ABS(K28)<='Start Here'!$B$33,"NEAR — watch",IF(K28>0,"above price","below price")))
K29: =IF(OR(A29="",B29=""),"",IFERROR(IF(INDEX($B$6:$B$10,MATCH(A29,$A$6:$A$10,0))="","",(B29/INDEX($B$6:$B$10,MATCH(A29,$A$6:$A$10,0))-1)*100),"")) | L29: =IF(K29="","",IF(ABS(K29)<='Start Here'!$B$33,"NEAR — watch",IF(K29>0,"above price","below price")))
K30: =IF(OR(A30="",B30=""),"",IFERROR(IF(INDEX($B$6:$B$10,MATCH(A30,$A$6:$A$10,0))="","",(B30/INDEX($B$6:$B$10,MATCH(A30,$A$6:$A$10,0))-1)*100),"")) | L30: =IF(K30="","",IF(ABS(K30)<='Start Here'!$B$33,"NEAR — watch",IF(K30>0,"above price","below price")))
K31: =IF(OR(A31="",B31=""),"",IFERROR(IF(INDEX($B$6:$B$10,MATCH(A31,$A$6:$A$10,0))="","",(B31/INDEX($B$6:$B$10,MATCH(A31,$A$6:$A$10,0))-1)*100),"")) | L31: =IF(K31="","",IF(ABS(K31)<='Start Here'!$B$33,"NEAR — watch",IF(K31>0,"above price","below price")))
K32: =IF(OR(A32="",B32=""),"",IFERROR(IF(INDEX($B$6:$B$10,MATCH(A32,$A$6:$A$10,0))="","",(B32/INDEX($B$6:$B$10,MATCH(A32,$A$6:$A$10,0))-1)*100),"")) | L32: =IF(K32="","",IF(ABS(K32)<='Start Here'!$B$33,"NEAR — watch",IF(K32>0,"above price","below price")))
K33: =IF(OR(A33="",B33=""),"",IFERROR(IF(INDEX($B$6:$B$10,MATCH(A33,$A$6:$A$10,0))="","",(B33/INDEX($B$6:$B$10,MATCH(A33,$A$6:$A$10,0))-1)*100),"")) | L33: =IF(K33="","",IF(ABS(K33)<='Start Here'!$B$33,"NEAR — watch",IF(K33>0,"above price","below price")))
K34: =IF(OR(A34="",B34=""),"",IFERROR(IF(INDEX($B$6:$B$10,MATCH(A34,$A$6:$A$10,0))="","",(B34/INDEX($B$6:$B$10,MATCH(A34,$A$6:$A$10,0))-1)*100),"")) | L34: =IF(K34="","",IF(ABS(K34)<='Start Here'!$B$33,"NEAR — watch",IF(K34>0,"above price","below price")))
K35: =IF(OR(A35="",B35=""),"",IFERROR(IF(INDEX($B$6:$B$10,MATCH(A35,$A$6:$A$10,0))="","",(B35/INDEX($B$6:$B$10,MATCH(A35,$A$6:$A$10,0))-1)*100),"")) | L35: =IF(K35="","",IF(ABS(K35)<='Start Here'!$B$33,"NEAR — watch",IF(K35>0,"above price","below price")))
K36: =IF(OR(A36="",B36=""),"",IFERROR(IF(INDEX($B$6:$B$10,MATCH(A36,$A$6:$A$10,0))="","",(B36/INDEX($B$6:$B$10,MATCH(A36,$A$6:$A$10,0))-1)*100),"")) | L36: =IF(K36="","",IF(ABS(K36)<='Start Here'!$B$33,"NEAR — watch",IF(K36>0,"above price","below price")))
... K52: =IF(OR(A52="",B52=""),"",IFERROR(IF(INDEX($B$6:$B$10,MATCH(A52,$A$6:$A$10,0))="","",(B52/INDEX($B$6:$B$10,MATCH(A52,$A$6:$A$10,0))-1)*100),"")) | L52: =IF(K52="","",IF(ABS(K52)<='Start Here'!$B$33,"NEAR — watch",IF(K52>0,"above price","below price")))

Sheet Journal
A1: Bias Journal | K1: ← Start Here
A2: One row per bias deduced
A4: Date | B4: Instrument | C4: Bias | D4: Score | E4: Risk regime | F4: Key driver | G4: Next catalyst | H4: Invalidation | I4: Outcome after 1 week | J4: Was the bias right? | K4: Lesson
A5: 46284 | B5: XAUUSD | C5: FLAT | D5: 0 | E5: RISK-ON | F5: Tailwinds (CB buying, ETF inflows, Gulf risk) cancelled by real yields at 18-yr high after first Fed hike in 3 yrs | G5: Next Fed meeting / US CPI | H5: LONG if real yields −15 bp or DXY −1%

Sheet Hub
A1: Hub — where to go for everything that doesn't live in this workbook | H1: ← Start Here
A2: Click a link, read, then write ONE line back here. The detail stays at the source; only your conclusion comes back.
A4: A. COUNTRY HUB — the story behind every currency
A5: Currency | B5: Situation in one line | C5: Main theme / risk | D5: Last checked | E5: Status | F5: Central bank | G5: Data + calendar | H5: News
A6: USD | E6: =IF(D6="","NOT CHECKED",IF(TODAY()-D6>14,"STALE","OK")) -> NOT CHECKED | F6: Fed ↗ | G6: Trading Econ ↗ | H6: News ↗
A7: EUR | E7: =IF(D7="","NOT CHECKED",IF(TODAY()-D7>14,"STALE","OK")) -> NOT CHECKED | F7: ECB ↗ | G7: Trading Econ ↗ | H7: News ↗
A8: GBP | E8: =IF(D8="","NOT CHECKED",IF(TODAY()-D8>14,"STALE","OK")) -> NOT CHECKED | F8: BoE ↗ | G8: Trading Econ ↗ | H8: News ↗
A9: JPY | B9: EXAMPLE: BoJ hiked, yet yen still weak; Japan + US intervened 31 Jul near 164 | C9: EXAMPLE: rate gap still wide; 160 is the political line | D9: 46286 | E9: =IF(D9="","NOT CHECKED",IF(TODAY()-D9>14,"STALE","OK")) -> OK | F9: BoJ ↗ | G9: Trading Econ ↗ | H9: News ↗
A10: AUD | E10: =IF(D10="","NOT CHECKED",IF(TODAY()-D10>14,"STALE","OK")) -> NOT CHECKED | F10: RBA ↗ | G10: Trading Econ ↗ | H10: News ↗
A11: NZD | E11: =IF(D11="","NOT CHECKED",IF(TODAY()-D11>14,"STALE","OK")) -> NOT CHECKED | F11: RBNZ ↗ | G11: Trading Econ ↗ | H11: News ↗
A12: CAD | E12: =IF(D12="","NOT CHECKED",IF(TODAY()-D12>14,"STALE","OK")) -> NOT CHECKED | F12: BoC ↗ | G12: Trading Econ ↗ | H12: News ↗
A13: CHF | E13: =IF(D13="","NOT CHECKED",IF(TODAY()-D13>14,"STALE","OK")) -> NOT CHECKED | F13: SNB ↗ | G13: Trading Econ ↗ | H13: News ↗
A14: Only fill the currencies you actually trade. STALE = more than 14 days since you last read up.
A16: B. WHO HOLDS WHAT — governments, central banks and big positioning
A17: What | B17: Why it matters for you | C17: What changed? (one line) | D17: Last checked | E17: Updates | F17: Source
A18: Foreign holders of US Treasuries (Japan, China, UK…) | B18: Big holders selling = pressure on US yields and the dollar. Japan selling can signal FX defence. | E18: Monthly | F18: US Treasury TIC ↗
A19: Central-bank gold reserves / buying | B19: The main support under gold. Slower buying weakens the floor in Key Levels. | E19: Monthly | F19: World Gold Council ↗
A20: Reserve currency shares (USD, EUR, JPY…) | B20: Slow structural trend — is the world diversifying away from the dollar? | E20: Quarterly | F20: IMF COFER ↗
A21: Japan FX intervention amounts | B21: Confirms when and how much Japan acted → update USDJPY policy lines. | E21: Monthly | F21: Japan MoF ↗
A22: Speculator positioning (CFTC COT) | B22: Not governments, but shows crowded trades that can snap back. | E22: Weekly (Fri) | F22: CFTC ↗
A24: C. WHERE IS MONEY MOVING? — risk-on vs risk-off barometer (weekly)
A25: Gauge | B25: Reads RISK-ON when… | C25: Your read | D25: Where to check
A26: AUD/JPY | B26: Rising — money leaving the safe-haven yen for higher-yielding AUD | C26: RISK-ON | D26: TradingView ↗
A27: Copper ÷ gold | B27: Rising — growth metal beating the safe-haven metal. In TradingView type: HG1!/GC1! | C27: NEUTRAL | D27: TradingView ↗
A28: US high-yield credit spread | B28: Falling — lenders relaxed about risky borrowers (FRED BAMLH0A0HYM2) | C28: RISK-ON | D28: FRED ↗
A29: Discretionary ÷ staples stocks | B29: Rising — investors buying 'wants' over 'needs'. In TradingView type: XLY/XLP | C29: NEUTRAL | D29: TradingView ↗
A30: Asset-class scoreboard | B30: Stocks & commodities lead, bonds/gold/yen lag. Shows the week's leaders at a glance. | C30: RISK-OFF | D30: Finviz futures ↗
A31: Sentiment | B31: Greed. (Extreme greed = crowded, watch for reversal.) | C31: NEUTRAL | D31: CNN Fear & Greed ↗
A33: Barometer result | B33: =COUNTIF(C26:C31,"RISK-ON")&" risk-on · "&COUNTIF(C26:C31,"RISK-OFF")&" risk-off · "&COUNTIF(C26:C31,"NEUTRAL")&" neutral" -> 2 risk-on · 1 risk-off · 3 neutral | C33: =IF(COUNTA(C26:C31)<6,"ENTER READS",IF(COUNTIF(C26:C31,"RISK-ON")-COUNTIF(C26:C31,"RISK-OFF")>=2,"RISK-ON",IF(COUNTIF(C26:C31,"RISK-OFF")-COUNTIF(C26:C31,"RISK-ON")>=2,"RISK-OFF","MIXED"))) -> MIXED
A34: VIX regime (Risk & Gold) | C34: ='Risk & Gold'!B8 -> RISK-ON
A35: Do they agree? | C35: =IF(OR(C33="MIXED",C34="CAUTION"),"PARTLY — size down",IF(C33=C34,"YES","NO — trust neither, size down")) -> PARTLY — size down
A37: D. COUNTRY DEEP-DIVE — paste into Claude (in your Trading project) when you need the full story
A38: Give me a country brief for [CURRENCY] as of today. Search current sources. Cover: 1) the central bank's last decision, vote and guidance, 2) latest inflation, jobs and growth prints vs expectations, 3) what the market prices for the next 3 meetings, 4) political/fiscal risks, 5) government or central-bank FX activity and big official holders, 6) the next 3 catalysts with dates. End with ONE line I can paste into my Hub, and tell me what would change the picture.
