Workbook

Sheet Guide
A1: Macro Tracker — Layer 1 (Macro Permission)
A2: Purpose: one weekly bias per instrument — LONG / SHORT / FLAT — with an expiry date. This is a filter, never an entry signal.
A4: ROUTINE (every 2 days) | E4: SHEET INDEX
A5: 1. Claude runs the full update cycle every 2 days (Prompts sheet → P0) and logs it on the Update Log. | E5: Sheet (click to open) | F5: What it's for | G5: When
A6: 2. User reads the Update Log (mark OK / Question / Revert) and the Calendar: what changed, what is coming. | E6: Bias ↗ | F6: FINAL BIAS per pair — what Layers 2–4 may trade | G6: Read weekly
A7: 3. User opens Bias Builder: model bias vs AI bias, then sets the User bias and User read per pair / currency. | E7: Compare ↗ | F7: Two currencies side by side — does the evidence back the call? | G7: Before a new idea
A8: 4. Bias: User enters today’s date in “Last reviewed” and writes the invalidation for each pair. | E8: Scorecard ↗ | F8: Macro data per currency → −1/0/+1 scores and stance | G8: Fill weekly
A9: 4b. Journal: User logs one line per instrument — bias, key driver, next catalyst — and every trade in the trade journal to the right (entry, stop, R, plan followed, emotion). | E9: Risk & Gold ↗ | F9: VIX risk regime + gold drivers → gold bias | G9: Fill weekly
A10: 5. After a tier-1 event (CPI, jobs, central-bank decision): run P8 for that event, or P4 for that currency. | E10: Key Levels ↗ | F10: Price levels where big players acted, with distance to price | G10: Fill weekly
E11: Hub ↗ | F11: Links out + one-line story per currency, risk barometer | G11: Fill weekly / monthly
A12: UNITS & CONVENTIONS | E12: Journal ↗ | F12: Bias journal (one row per bias) + trade journal on the right (one row per trade) — the User’s tuning data | G12: Log weekly
A13: • Percentages are typed as plain numbers: 3.1 means 3.1%. | E13: Calendar ↗ | F13: Economic calendar — this week + 4-month overview, colour-coded by country and type | G13: Open daily
A14: • Yield changes are in basis points (bp): 100 bp = 1 percentage point. | E14: Events ↗ | F14: The event list behind the Calendar | G14: Claude weekly
A15: • Text that starts with 'EXAMPLE:' is illustrative — the User overwrites it with their own read. | E15: Sources ↗ | F15: Where every input comes from, and who fills it | G15: Reference
A16: • Dates: type them as dates (e.g. 21-9-2026), never as a formula like =TODAY(). | E16: Bias Builder ↗ | F16: Per-country evidence (central bank, market pricing, treasury, indicators) + AI bias vs yours | G16: Before setting a bias
E17: Update Log ↗ | F17: What each update run changed — newest at the top | G17: After every run
A18: RULES / THRESHOLDS (every formula reads from here) | E18: Prompts ↗ | F18: All update prompts (P0 full cycle … P9) + the update rules | G18: To run or schedule
A19: Rule | B19: Value | C19: What it does | E19: COLOUR LEGEND
A20: Inflation 'near target' band (pp) | B20: 0.5 | C20: Core CPI falling AND within this distance of target (or below) = −1. Above target and not falling = +1. | E20: CELL TYPES — what the User may touch
A21: Unemployment change (pp) | B21: 0.2 | C21: Unemployment down ≥ this over 3 months = +1 (tight). Up ≥ this = −1 (weakening). | E21: 3.10 | F21: Input — type here | G21: Every sheet
A22: PMI expansion level | B22: 52 | C22: Composite PMI ≥ this = +1. | E22: 1 | F22: Formula — calculated, don't overwrite | G22: Every sheet
A23: PMI contraction level | B23: 48 | C23: Composite PMI ≤ this = −1. | E23: -1 | F23: Linked — pulled from another sheet | G23: Bias, Compare, Risk & Gold, Hub
A24: 2Y yield move (bp, 1 month) | B24: 15 | C24: Market repricing proxy. 2Y up ≥ this = +1 (hawkish repricing), down ≥ this = −1. | E24: Column header | F24: Table header | G24: Every sheet
A25: Currency stance cut-off (score) | B25: 2 | C25: Total ≥ +2 = HAWKISH, ≤ −2 = DOVISH, otherwise NEUTRAL. | E25: Fed ↗ | F25: Hyperlink — opens a website or sheet | G25: Hub, this sheet
A26: Pair score difference needed | B26: 2 | C26: Base score minus quote score must be ≥ this for a LONG signal (≤ −this for SHORT). | E26: Help text | F26: Note / explanation — read only | G26: Every sheet
A27: 2Y differential confirmation (bp) | B27: 10 | C27: The 2Y yield spread must have moved ≥ this in the same direction over 1 month, otherwise FLAT. | E27: ⚠ Warning | F27: Warning — check before relying on it | G27: Scorecard, Key Levels
A28: VIX calm level | B28: 18 | C28: From investing Layer 3: VIX below this (and S&P above 200-day) = RISK-ON. | E28: — | F28: Not applicable for this row | G28: Bias (gold row)
A29: VIX stress level | B29: 30 | C29: From investing Layer 3: VIX above this = RISK-OFF. | E29: Give me a brief… | F29: Prompt — copy and paste into Claude | G29: Hub
A30: Real-yield move for gold (bp) | B30: 15 | C30: US 10Y real yield down ≥ this over 1 month = +1 for gold; up ≥ this = −1. | E30: SIGNALS — colour changes by itself
A31: Dollar move for gold (%) | B31: 1 | C31: Dollar index down ≥ this % over 1 month = +1 for gold; up ≥ this = −1. | E31: LONG | F31: Long / hawkish / supportive: LONG · HAWKISH · RISK-ON · ACTIVE · OK · BACKS THE CALL · STRONG · YES | G31: Bias, Compare, Scorecard, Risk & Gold, Hub, Journal
A32: Gold score cut-off | B32: 2 | C32: Gold total ≥ +2 = LONG, ≤ −2 = SHORT. | E32: SHORT | F32: Short / dovish / against: SHORT · DOVISH · RISK-OFF · EXPIRED · STALE · AGAINST · WEAK · NO | G32: Bias, Compare, Scorecard, Risk & Gold, Hub, Journal
A33: Key level 'near' distance (%) | B33: 0.5 | C33: Key Levels flags a level as NEAR when price is within this % of it. | E33: NOT REVIEWED | F33: Needs attention: ENTER DATA · NOT REVIEWED · NOT CHECKED · CAUTION · MIXED · PARTLY · MODERATE · NEAR · yields NO | G33: Every sheet except Guide
A34: Bias valid for (days) | B34: 7 | C34: After this many days without review the bias shows EXPIRED — treat as FLAT. | E34: FLAT | F34: No edge — stand aside: FLAT · NEUTRAL | G34: Bias, Compare, Scorecard, Risk & Gold, Hub, Journal
A35: Starting thresholds are Claude's suggestions, not tested values — tune them after journaling a few months. | E35: +1 | F35: Score above zero (green) — supports the currency / gold | G35: Scorecard, Risk & Gold
E36: −1 | F36: Score below zero (red) — works against it | G36: Scorecard, Risk & Gold
A37: DATA SOURCES | E37: ■■■ | F37: Bar: green = base currency wins this factor | G37: Compare
A38: Fixed sources | B38: Every input has ONE fixed source — see the Sources sheet ↗ | E38: ■■■ | F38: Bar: red = quote currency wins this factor | G38: Compare
A39: US data | B39: FRED: core CPI, unemployment, 2Y, real yield, VIX, S&P 500, HY spread | E39: KEY LEVEL TYPES
A40: EUR / GBP / JPY data | B40: Eurostat · ONS · Statistics Bureau of Japan · Bundesbank · Japan MoF | E40: Policy line | F40: Government / central bank acted here | G40: Key Levels
A41: PMIs + prices | B41: S&P Global / HCOB final PMIs · TradingView (prices, 2Y yields, DXY, VIX, S&P, barometer) | E41: Options / GEX | F41: Big option strikes or expiries | G41: Key Levels
...

Sheet Calendar
A1: Economic Calendar | AA1: ← Guide
A2: Open this every morning. Week view + four-month overview, fed by the Events sheet. Times are Amsterdam time (CET/CEST).
A4: TODAY
A5: Today | D5: =TODAY() -> 46310 | F5: Week to show (0 = this week, 1 = next, −1 = last) | H5: 0 | J5: =COUNTIFS(Events!$A$5:$A$304,TODAY(),Events!$K$5:$K$304,">="&$AC$5)&" event(s) today" -> 11 event(s) today | AC5: =IF($D$6="High only",3,IF($D$6="High + Medium",2,1)) -> 2
A6: Show events | D6: High + Medium | F6: Week starting (Monday) | H6: =TODAY()-WEEKDAY(TODAY(),3)+IF(WEEKDAY(TODAY(),2)>5,7,0)+7*$H$5 -> 46307
A7: Next high-impact event | D7: =IFERROR(INDEX(Events!$C$5:$C$304,MATCH(_xlfn.MINIFS(Events!$L$5:$L$304,Events!$D$5:$D$304,"High",Events!$L$5:$L$304,">="&NOW()),Events!$L$5:$L$304,0))&" "&INDEX(Events!$F$5:$F$304,MATCH(_xlfn.MINIFS(Events!$L$5:$L$304,Events!$D$5:$D$304,"High",Events!$L$5:$L$304,">="&NOW()),Events!$L$5:$L$304,0))&" — "&TEXT(_xlfn.MINIFS(Events!$L$5:$L$304,Events!$D$5:$D$304,"High",Events!$L$5:$L$304,">="&NOW()),"ddd d mmm hh:mm")&" (in "&INT(_xlfn.MINIFS(Events!$L$5:$L$304,Events!$D$5:$D$304,"High",Events!$L$5:$L$304,">="&NOW()))-TODAY()&" days)","none scheduled") -> USD Core PPI m/m — Thu 15 Oct 14:30 (in 0 days)
A9: THIS WEEK | M9: MONTH AT A GLANCE
A10: # | B10: =$H$6+0 -> 46307 | D10: =$H$6+1 -> 46308 | F10: =$H$6+2 -> 46309 | H10: =$H$6+3 -> 46310 | J10: =$H$6+4 -> 46311 | M10: =TEXT(DATE(YEAR($H$6),MONTH($H$6),1),"mmmm yyyy") -> October 2026 | U10: =TEXT(EDATE(DATE(YEAR($H$6),MONTH($H$6),1),1),"mmmm yyyy") -> November 2026
A11: 1 | B11: =IF($AC11="","",IFERROR(INDEX({"CB","SPK","GOV","INF","JOB","BIZ","HOL"},MATCH(INDEX(Events!$E$5:$E$304,$AC11),{"Central bank","CB speech","Government","Inflation","Jobs","Growth & business","Holiday"},0)),"?")) -> HOL | C11: =IF($AC11="","",IF(INDEX(Events!$D$5:$D$304,$AC11)="High","● ",IF(INDEX(Events!$D$5:$D$304,$AC11)="Medium","○ "," "))&IF(INDEX(Events!$B$5:$B$304,$AC11)="","all day",TEXT(INDEX(Events!$B$5:$B$304,$AC11),"hh:mm"))&" "&INDEX(Events!$C$5:$C$304,$AC11)&" "&INDEX(Events!$F$5:$F$304,$AC11)) -> all day JPY Bank Holiday | D11: =IF($AD11="","",IFERROR(INDEX({"CB","SPK","GOV","INF","JOB","BIZ","HOL"},MATCH(INDEX(Events!$E$5:$E$304,$AD11),{"Central bank","CB speech","Government","Inflation","Jobs","Growth & business","Holiday"},0)),"?")) | E11: =IF($AD11="","",IF(INDEX(Events!$D$5:$D$304,$AD11)="High","● ",IF(INDEX(Events!$D$5:$D$304,$AD11)="Medium","○ "," "))&IF(INDEX(Events!$B$5:$B$304,$AD11)="","all day",TEXT(INDEX(Events!$B$5:$B$304,$AD11),"hh:mm"))&" "&INDEX(Events!$C$5:$C$304,$AD11)&" "&INDEX(Events!$F$5:$F$304,$AD11)) | F11: =IF($AE11="","",IFERROR(INDEX({"CB","SPK","GOV","INF","JOB","BIZ","HOL"},MATCH(INDEX(Events!$E$5:$E$304,$AE11),{"Central bank","CB speech","Government","Inflation","Jobs","Growth & business","Holiday"},0)),"?")) -> SPK | G11: =IF($AE11="","",IF(INDEX(Events!$D$5:$D$304,$AE11)="High","● ",IF(INDEX(Events!$D$5:$D$304,$AE11)="Medium","○ "," "))&IF(INDEX(Events!$B$5:$B$304,$AE11)="","all day",TEXT(INDEX(Events!$B$5:$B$304,$AE11),"hh:mm"))&" "&INDEX(Events!$C$5:$C$304,$AE11)&" "&INDEX(Events!$F$5:$F$304,$AE11)) -> ○ 04:10 EUR ECB President Lagarde Speaks | H11: =IF($AF11="","",IFERROR(INDEX({"CB","SPK","GOV","INF","JOB","BIZ","HOL"},MATCH(INDEX(Events!$E$5:$E$304,$AF11),{"Central bank","CB speech","Government","Inflation","Jobs","Growth & business","Holiday"},0)),"?")) -> JOB | I11: =IF($AF11="","",IF(INDEX(Events!$D$5:$D$304,$AF11)="High","● ",IF(INDEX(Events!$D$5:$D$304,$AF11)="Medium","○ "," "))&IF(INDEX(Events!$B$5:$B$304,$AF11)="","all day",TEXT(INDEX(Events!$B$5:$B$304,$AF11),"hh:mm"))&" "&INDEX(Events!$C$5:$C$304,$AF11)&" "&INDEX(Events!$F$5:$F$304,$AF11)) -> ● 02:30 AUD Employment Change | J11: =IF($AG11="","",IFERROR(INDEX({"CB","SPK","GOV","INF","JOB","BIZ","HOL"},MATCH(INDEX(Events!$E$5:$E$304,$AG11),{"Central bank","CB speech","Government","Inflation","Jobs","Growth & business","Holiday"},0)),"?")) -> SPK | K11: =IF($AG11="","",IF(INDEX(Events!$D$5:$D$304,$AG11)="High","● ",IF(INDEX(Events!$D$5:$D$304,$AG11)="Medium","○ "," "))&IF(INDEX(Events!$B$5:$B$304,$AG11)="","all day",TEXT(INDEX(Events!$B$5:$B$304,$AG11),"hh:mm"))&" "&INDEX(Events!$C$5:$C$304,$AG11)&" "&INDEX(Events!$F$5:$F$304,$AG11)) -> ● 04:00 GBP BOE Gov Bailey Speaks | M11: Mo | N11: Tu | O11: We | P11: Th | Q11: Fr | R11: Sa | S11: Su | U11: Mo | V11: Tu | W11: We | X11: Th | Y11: Fr | Z11: Sa | AA11: Su | AC11: =IFERROR(MATCH(TEXT(B$10,"yyyymmdd")&"|"&$A11,Events!$M$5:$M$304,0),"") -> 23 | AD11: =IFERROR(MATCH(TEXT(D$10,"yyyymmdd")&"|"&$A11,Events!$M$5:$M$304,0),"") | AE11: =IFERROR(MATCH(TEXT(F$10,"yyyymmdd")&"|"&$A11,Events!$M$5:$M$304,0),"") -> 25 | AF11: =IFERROR(MATCH(TEXT(H$10,"yyyymmdd")&"|"&$A11,Events!$M$5:$M$304,0),"") -> 33 | AG11: =IFERROR(MATCH(TEXT(J$10,"yyyymmdd")&"|"&$A11,Events!$M$5:$M$304,0),"") -> 44
A12: 2 | B12: =IF($AC12="","",IFERROR(INDEX({"CB","SPK","GOV","INF","JOB","BIZ","HOL"},MATCH(INDEX(Events!$E$5:$E$304,$AC12),{"Central bank","CB speech","Government","Inflation","Jobs","Growth & business","Holiday"},0)),"?")) -> HOL | C12: =IF($AC12="","",IF(INDEX(Events!$D$5:$D$304,$AC12)="High","● ",IF(INDEX(Events!$D$5:$D$304,$AC12)="Medium","○ "," "))&IF(INDEX(Events!$B$5:$B$304,$AC12)="","all day",TEXT(INDEX(Events!$B$5:$B$304,$AC12),"hh:mm"))&" "&INDEX(Events!$C$5:$C$304,$AC12)&" "&INDEX(Events!$F$5:$F$304,$AC12)) -> all day USD Bank Holiday | D12: =IF($AD12="","",IFERROR(INDEX({"CB","SPK","GOV","INF","JOB","BIZ","HOL"},MATCH(INDEX(Events!$E$5:$E$304,$AD12),{"Central bank","CB speech","Government","Inflation","Jobs","Growth & business","Holiday"},0)),"?")) | E12: =IF($AD12="","",IF(INDEX(Events!$D$5:$D$304,$AD12)="High","● ",IF(INDEX(Events!$D$5:$D$304,$AD12)="Medium","○ "," "))&IF(INDEX(Events!$B$5:$B$304,$AD12)="","all day",TEXT(INDEX(Events!$B$5:$B$304,$AD12),"hh:mm"))&" "&INDEX(Events!$C$5:$C$304,$AD12)&" "&INDEX(Events!$F$5:$F$304,$AD12)) | F12: =IF($AE12="","",IFERROR(INDEX({"CB","SPK","GOV","INF","JOB","BIZ","HOL"},MATCH(INDEX(Events!$E$5:$E$304,$AE12),{"Central bank","CB speech","Government","Inflation","Jobs","Growth & business","Holiday"},0)),"?")) -> SPK | G12: =IF($AE12="","",IF(INDEX(Events!$D$5:$D$304,$AE12)="High","● ",IF(INDEX(Events!$D$5:$D$304,$AE12)="Medium","○ "," "))&IF(INDEX(Events!$B$5:$B$304,$AE12)="","all day",TEXT(INDEX(Events!$B$5:$B$304,$AE12),"hh:mm"))&" "&INDEX(Events!$C$5:$C$304,$AE12)&" "&INDEX(Events!$F$5:$F$304,$AE12)) -> ○ 07:30 GBP BOE Gov Bailey Speaks | H12: =IF($AF12="","",IFERROR(INDEX({"CB","SPK","GOV","INF","JOB","BIZ","HOL"},MATCH(INDEX(Events!$E$5:$E$304,$AF12),{"Central bank","CB speech","Government","Inflation","Jobs","Growth & business","Holiday"},0)),"?")) -> JOB | I12: =IF($AF12="","",IF(INDEX(Events!$D$5:$D$304,$AF12)="High","● ",IF(INDEX(Events!$D$5:$D$304,$AF12)="Medium","○ "," "))&IF(INDEX(Events!$B$5:$B$304,$AF12)="","all day",TEXT(INDEX(Events!$B$5:$B$304,$AF12),"hh:mm"))&" "&INDEX(Events!$C$5:$C$304,$AF12)&" "&INDEX(Events!$F$5:$F$304,$AF12)) -> ● 02:30 AUD Unemployment Rate | J12: =IF($AG12="","",IFERROR(INDEX({"CB","SPK","GOV","INF","JOB","BIZ","HOL"},MATCH(INDEX(Events!$E$5:$E$304,$AG12),{"Central bank","CB speech","Government","Inflation","Jobs","Growth & business","Holiday"},0)),"?")) -> SPK | K12: =IF($AG12="","",IF(INDEX(Events!$D$5:$D$304,$AG12)="High","● ",IF(INDEX(Events!$D$5:$D$304,$AG12)="Medium","○ "," "))&IF(INDEX(Events!$B$5:$B$304,$AG12)="","all day",TEXT(INDEX(Events!$B$5:$B$304,$AG12),"hh:mm"))&" "&INDEX(Events!$C$5:$C$304,$AG12)&" "&INDEX(Events!$F$5:$F$304,$AG12)) -> ● 05:30 USD Fed Chairman Warsh Speaks | M12: =(DATE(YEAR($H$6),MONTH($H$6),1)-WEEKDAY(DATE(YEAR($H$6),MONTH($H$6),1),3))+0 -> 46293 | N12: =(DATE(YEAR($H$6),MONTH($H$6),1)-WEEKDAY(DATE(YEAR($H$6),MONTH($H$6),1),3))+1 -> 46294 | O12: =(DATE(YEAR($H$6),MONTH($H$6),1)-WEEKDAY(DATE(YEAR($H$6),MONTH($H$6),1),3))+2 -> 46295 | P12: =(DATE(YEAR($H$6),MONTH($H$6),1)-WEEKDAY(DATE(YEAR($H$6),MONTH($H$6),1),3))+3 -> 46296 | Q12: =(DATE(YEAR($H$6),MONTH($H$6),1)-WEEKDAY(DATE(YEAR($H$6),MONTH($H$6),1),3))+4 -> 46297 | R12: =(DATE(YEAR($H$6),MONTH($H$6),1)-WEEKDAY(DATE(YEAR($H$6),MONTH($H$6),1),3))+5 -> 46298 | S12: =(DATE(YEAR($H$6),MONTH($H$6),1)-WEEKDAY(DATE(YEAR($H$6),MONTH($H$6),1),3))+6 -> 46299 | U12: =(EDATE(DATE(YEAR($H$6),MONTH($H$6),1),1)-WEEKDAY(EDATE(DATE(YEAR($H$6),MONTH($H$6),1),1),3))+0 -> 46321 | V12: =(EDATE(DATE(YEAR($H$6),MONTH($H$6),1),1)-WEEKDAY(EDATE(DATE(YEAR($H$6),MONTH($H$6),1),1),3))+1 -> 46322 | W12: =(EDATE(DATE(YEAR($H$6),MONTH($H$6),1),1)-WEEKDAY(EDATE(DATE(YEAR($H$6),MONTH($H$6),1),1),3))+2 -> 46323 | X12: =(EDATE(DATE(YEAR($H$6),MONTH($H$6),1),1)-WEEKDAY(EDATE(DATE(YEAR($H$6),MONTH($H$6),1),1),3))+3 -> 46324 | Y12: =(EDATE(DATE(YEAR($H$6),MONTH($H$6),1),1)-WEEKDAY(EDATE(DATE(YEAR($H$6),MONTH($H$6),1),1),3))+4 -> 46325 | Z12: =(EDATE(DATE(YEAR($H$6),MONTH($H$6),1),1)-WEEKDAY(EDATE(DATE(YEAR($H$6),MONTH($H$6),1),1),3))+5 -> 46326 | AA12: =(EDATE(DATE(YEAR($H$6),MONTH($H$6),1),1)-WEEKDAY(EDATE(DATE(YEAR($H$6),MONTH($H$6),1),1),3))+6 -> 46327 | AC12: =IFERROR(MATCH(TEXT(B$10,"yyyymmdd")&"|"&$A12,Events!$M$5:$M$304,0),"") -> 24 | AD12: =IFERROR(MATCH(TEXT(D$10,"yyyymmdd")&"|"&$A12,Events!$M$5:$M$304,0),"") | AE12: =IFERROR(MATCH(TEXT(F$10,"yyyymmdd")&"|"&$A12,Events!$M$5:$M$304,0),"") -> 26 | AF12: =IFERROR(MATCH(TEXT(H$10,"yyyymmdd")&"|"&$A12,Events!$M$5:$M$304,0),"") -> 34 | AG12: =IFERROR(MATCH(TEXT(J$10,"yyyymmdd")&"|"&$A12,Events!$M$5:$M$304,0),"") -> 45
A13: 3 | B13: =IF($AC13="","",IFERROR(INDEX({"CB","SPK","GOV","INF","JOB","BIZ","HOL"},MATCH(INDEX(Events!$E$5:$E$304,$AC13),{"Central bank","CB speech","Government","Inflation","Jobs","Growth & business","Holiday"},0)),"?")) | C13: =IF($AC13="","",IF(INDEX(Events!$D$5:$D$304,$AC13)="High","● ",IF(INDEX(Events!$D$5:$D$304,$AC13)="Medium","○ "," "))&IF(INDEX(Events!$B$5:$B$304,$AC13)="","all day",TEXT(INDEX(Events!$B$5:$B$304,$AC13),"hh:mm"))&" "&INDEX(Events!$C$5:$C$304,$AC13)&" "&INDEX(Events!$F$5:$F$304,$AC13)) | D13: =IF($AD13="","",IFERROR(INDEX({"CB","SPK","GOV","INF","JOB","BIZ","HOL"},MATCH(INDEX(Events!$E$5:$E$304,$AD13),{"Central bank","CB speech","Government","Inflation","Jobs","Growth & business","Holiday"},0)),"?")) | E13: =IF($AD13="","",IF(INDEX(Events!$D$5:$D$304,$AD13)="High","● ",IF(INDEX(Events!$D$5:$D$304,$AD13)="Medium","○ "," "))&IF(INDEX(Events!$B$5:$B$304,$AD13)="","all day",TEXT(INDEX(Events!$B$5:$B$304,$AD13),"hh:mm"))&" "&INDEX(Events!$C$5:$C$304,$AD13)&" "&INDEX(Events!$F$5:$F$304,$AD13)) | F13: =IF($AE13="","",IFERROR(INDEX({"CB","SPK","GOV","INF","JOB","BIZ","HOL"},MATCH(INDEX(Events!$E$5:$E$304,$AE13),{"Central bank","CB speech","Government","Inflation","Jobs","Growth & business","Holiday"},0)),"?")) -> SPK | G13: =IF($AE13="","",IF(INDEX(Events!$D$5:$D$304,$AE13)="High","● ",IF(INDEX(Events!$D$5:$D$304,$AE13)="Medium","○ "," "))&IF(INDEX(Events!$B$5:$B$304,$AE13)="","all day",TEXT(INDEX(Events!$B$5:$B$304,$AE13),"hh:mm"))&" "&INDEX(Events!$C$5:$C$304,$AE13)&" "&INDEX(Events!$F$5:$F$304,$AE13)) -> ○ 10:30 EUR ECB President Lagarde Speaks | H13: =IF($AF13="","",IFERROR(INDEX({"CB","SPK","GOV","INF","JOB","BIZ","HOL"},MATCH(INDEX(Events!$E$5:$E$304,$AF13),{"Central bank","CB speech","Government","Inflation","Jobs","Growth & business","Holiday"},0)),"?")) -> BIZ | I13: =IF($AF13="","",IF(INDEX(Events!$D$5:$D$304,$AF13)="High","● ",IF(INDEX(Events!$D$5:$D$304,$AF13)="Medium","○ "," "))&IF(INDEX(Events!$B$5:$B$304,$AF13)="","all day",TEXT(INDEX(Events!$B$5:$B$304,$AF13),"hh:mm"))&" "&INDEX(Events!$C$5:$C$304,$AF13)&" "&INDEX(Events!$F$5:$F$304,$AF13)) -> ● 08:00 GBP GDP m/m | J13: =IF($AG13="","",IFERROR(INDEX({"CB","SPK","GOV","INF","JOB","BIZ","HOL"},MATCH(INDEX(Events!$E$5:$E$304,$AG13),{"Central bank","CB speech","Government","Inflation","Jobs","Growth & business","Holiday"},0)),"?")) | K13: =IF($AG13="","",IF(INDEX(Events!$D$5:$D$304,$AG13)="High","● ",IF(INDEX(Events!$D$5:$D$304,$AG13)="Medium","○ "," "))&IF(INDEX(Events!$B$5:$B$304,$AG13)="","all day",TEXT(INDEX(Events!$B$5:$B$304,$AG13),"hh:mm"))&" "&INDEX(Events!$C$5:$C$304,$AG13)&" "&INDEX(Events!$F$5:$F$304,$AG13)) | M13: =(DATE(YEAR($H$6),MONTH($H$6),1)-WEEKDAY(DATE(YEAR($H$6),MONTH($H$6),1),3))+7 -> 46300 | N13: =(DATE(YEAR($H$6),MONTH($H$6),1)-WEEKDAY(DATE(YEAR($H$6),MONTH($H$6),1),3))+8 -> 46301 | O13: =(DATE(YEAR($H$6),MONTH($H$6),1)-WEEKDAY(DATE(YEAR($H$6),MONTH($H$6),1),3))+9 -> 46302 | P13: =(DATE(YEAR($H$6),MONTH($H$6),1)-WEEKDAY(DATE(YEAR($H$6),MONTH($H$6),1),3))+10 -> 46303 | Q13: =(DATE(YEAR($H$6),MONTH($H$6),1)-WEEKDAY(DATE(YEAR($H$6),MONTH($H$6),1),3))+11 -> 46304 | R13: =(DATE(YEAR($H$6),MONTH($H$6),1)-WEEKDAY(DATE(YEAR($H$6),MONTH($H$6),1),3))+12 -> 46305 | S13: =(DATE(YEAR($H$6),MONTH($H$6),1)-WEEKDAY(DATE(YEAR($H$6),MONTH($H$6),1),3))+13 -> 46306 | U13: =(EDATE(DATE(YEAR($H$6),MONTH($H$6),1),1)-WEEKDAY(EDATE(DATE(YEAR($H$6),MONTH($H$6),1),1),3))+7 -> 46328 | V13: =(EDATE(DATE(YEAR($H$6),MONTH($H$6),1),1)-WEEKDAY(EDATE(DATE(YEAR($H$6),MONTH($H$6),1),1),3))+8 -> 46329 | W13: =(EDATE(DATE(YEAR($H$6),MONTH($H$6),1),1)-WEEKDAY(EDATE(DATE(YEAR($H$6),MONTH($H$6),1),1),3))+9 -> 46330 | X13: =(EDATE(DATE(YEAR($H$6),MONTH($H$6),1),1)-WEEKDAY(EDATE(DATE(YEAR($H$6),MONTH($H$6),1),1),3))+10 -> 46331 | Y13: =(EDATE(DATE(YEAR($H$6),MONTH($H$6),1),1)-WEEKDAY(EDATE(DATE(YEAR($H$6),MONTH($H$6),1),1),3))+11 -> 46332 | Z13: =(EDATE(DATE(YEAR($H$6),MONTH($H$6),1),1)-WEEKDAY(EDATE(DATE(YEAR($H$6),MONTH($H$6),1),1),3))+12 -> 46333 | AA13: =(EDATE(DATE(YEAR($H$6),MONTH($H$6),1),1)-WEEKDAY(EDATE(DATE(YEAR($H$6),MONTH($H$6),1),1),3))+13 -> 46334 | AC13: =IFERROR(MATCH(TEXT(B$10,"yyyymmdd")&"|"&$A13,Events!$M$5:$M$304,0),"") | AD13: =IFERROR(MATCH(TEXT(D$10,"yyyymmdd")&"|"&$A13,Events!$M$5:$M$304,0),"") | AE13: =IFERROR(MATCH(TEXT(F$10,"yyyymmdd")&"|"&$A13,Events!$M$5:$M$304,0),"") -> 27 | AF13: =IFERROR(MATCH(TEXT(H$10,"yyyymmdd")&"|"&$A13,Events!$M$5:$M$304,0),"") -> 35 | AG13: =IFERROR(MATCH(TEXT(J$10,"yyyymmdd")&"|"&$A13,Events!$M$5:$M$304,0),"")
A14: 4 | B14: =IF($AC14="","",IFERROR(INDEX({"CB","SPK","GOV","INF","JOB","BIZ","HOL"},MATCH(INDEX(Events!$E$5:$E$304,$AC14),{"Central bank","CB speech","Government","Inflation","Jobs","Growth & business","Holiday"},0)),"?")) | C14: =IF($AC14="","",IF(INDEX(Events!$D$5:$D$304,$AC14)="High","● ",IF(INDEX(Events!$D$5:$D$304,$AC14)="Medium","○ "," "))&IF(INDEX(Events!$B$5:$B$304,$AC14)="","all day",TEXT(INDEX(Events!$B$5:$B$304,$AC14),"hh:mm"))&" "&INDEX(Events!$C$5:$C$304,$AC14)&" "&INDEX(Events!$F$5:$F$304,$AC14)) | D14: =IF($AD14="","",IFERROR(INDEX({"CB","SPK","GOV","INF","JOB","BIZ","HOL"},MATCH(INDEX(Events!$E$5:$E$304,$AD14),{"Central bank","CB speech","Government","Inflation","Jobs","Growth & business","Holiday"},0)),"?")) | E14: =IF($AD14="","",IF(INDEX(Events!$D$5:$D$304,$AD14)="High","● ",IF(INDEX(Events!$D$5:$D$304,$AD14)="Medium","○ "," "))&IF(INDEX(Events!$B$5:$B$304,$AD14)="","all day",TEXT(INDEX(Events!$B$5:$B$304,$AD14),"hh:mm"))&" "&INDEX(Events!$C$5:$C$304,$AD14)&" "&INDEX(Events!$F$5:$F$304,$AD14)) | F14: =IF($AE14="","",IFERROR(INDEX({"CB","SPK","GOV","INF","JOB","BIZ","HOL"},MATCH(INDEX(Events!$E$5:$E$304,$AE14),{"Central bank","CB speech","Government","Inflation","Jobs","Growth & business","Holiday"},0)),"?")) -> GOV | G14: =IF($AE14="","",IF(INDEX(Events!$D$5:$D$304,$AE14)="High","● ",IF(INDEX(Events!$D$5:$D$304,$AE14)="Medium","○ "," "))&IF(INDEX(Events!$B$5:$B$304,$AE14)="","all day",TEXT(INDEX(Events!$B$5:$B$304,$AE14),"hh:mm"))&" "&INDEX(Events!$C$5:$C$304,$AE14)&" "&INDEX(Events!$F$5:$F$304,$AE14)) -> ○ 12:15 EUR EU Economic Summit | H14: =IF($AF14="","",IFERROR(INDEX({"CB","SPK","GOV","INF","JOB","BIZ","HOL"},MATCH(INDEX(Events!$E$5:$E$304,$AF14),{"Central bank","CB speech","Government","Inflation","Jobs","Growth & business","Holiday"},0)),"?")) -> SPK | I14: =IF($AF14="","",IF(INDEX(Events!$D$5:$D$304,$AF14)="High","● ",IF(INDEX(Events!$D$5:$D$304,$AF14)="Medium","○ "," "))&IF(INDEX(Events!$B$5:$B$304,$AF14)="","all day",TEXT(INDEX(Events!$B$5:$B$304,$AF14),"hh:mm"))&" "&INDEX(Events!$C$5:$C$304,$AF14)&" "&INDEX(Events!$F$5:$F$304,$AF14)) -> ○ 09:30 GBP BOE Gov Bailey Speaks | J14: =IF($AG14="","",IFERROR(INDEX({"CB","SPK","GOV","INF","JOB","BIZ","HOL"},MATCH(INDEX(Events!$E$5:$E$304,$AG14),{"Central bank","CB speech","Government","Inflation","Jobs","Growth & business","Holiday"},0)),"?")) | K14: =IF($AG14="","",IF(INDEX(Events!$D$5:$D$304,$AG14)="High","● ",IF(INDEX(Events!$D$5:$D$304,$AG14)="Medium","○ "," "))&IF(INDEX(Events!$B$5:$B$304,$AG14)="","all day",TEXT(INDEX(Events!$B$5:$B$304,$AG14),"hh:mm"))&" "&INDEX(Events!$C$5:$C$304,$AG14)&" "&INDEX(Events!$F$5:$F$304,$AG14)) | M14: =(DATE(YEAR($H$6),MONTH($H$6),1)-WEEKDAY(DATE(YEAR($H$6),MONTH($H$6),1),3))+14 -> 46307 | N14: =(DATE(YEAR($H$6),MONTH($H$6),1)-WEEKDAY(DATE(YEAR($H$6),MONTH($H$6),1),3))+15 -> 46308 | O14: =(DATE(YEAR($H$6),MONTH($H$6),1)-WEEKDAY(DATE(YEAR($H$6),MONTH($H$6),1),3))+16 -> 46309 | P14: =(DATE(YEAR($H$6),MONTH($H$6),1)-WEEKDAY(DATE(YEAR($H$6),MONTH($H$6),1),3))+17 -> 46310 | Q14: =(DATE(YEAR($H$6),MONTH($H$6),1)-WEEKDAY(DATE(YEAR($H$6),MONTH($H$6),1),3))+18 -> 46311 | R14: =(DATE(YEAR($H$6),MONTH($H$6),1)-WEEKDAY(DATE(YEAR($H$6),MONTH($H$6),1),3))+19 -> 46312 | S14: =(DATE(YEAR($H$6),MONTH($H$6),1)-WEEKDAY(DATE(YEAR($H$6),MONTH($H$6),1),3))+20 -> 46313 | U14: =(EDATE(DATE(YEAR($H$6),MONTH($H$6),1),1)-WEEKDAY(EDATE(DATE(YEAR($H$6),MONTH($H$6),1),1),3))+14 -> 46335 | V14: =(EDATE(DATE(YEAR($H$6),MONTH($H$6),1),1)-WEEKDAY(EDATE(DATE(YEAR($H$6),MONTH($H$6),1),1),3))+15 -> 46336 | W14: =(EDATE(DATE(YEAR($H$6),MONTH($H$6),1),1)-WEEKDAY(EDATE(DATE(YEAR($H$6),MONTH($H$6),1),1),3))+16 -> 46337 | X14: =(EDATE(DATE(YEAR($H$6),MONTH($H$6),1),1)-WEEKDAY(EDATE(DATE(YEAR($H$6),MONTH($H$6),1),1),3))+17 -> 46338 | Y14: =(EDATE(DATE(YEAR($H$6),MONTH($H$6),1),1)-WEEKDAY(EDATE(DATE(YEAR($H$6),MONTH($H$6),1),1),3))+18 -> 46339 | Z14: =(EDATE(DATE(YEAR($H$6),MONTH($H$6),1),1)-WEEKDAY(EDATE(DATE(YEAR($H$6),MONTH($H$6),1),1),3))+19 -> 46340 | AA14: =(EDATE(DATE(YEAR($H$6),MONTH($H$6),1),1)-WEEKDAY(EDATE(DATE(YEAR($H$6),MONTH($H$6),1),1),3))+20 -> 46341 | AC14: =IFERROR(MATCH(TEXT(B$10,"yyyymmdd")&"|"&$A14,Events!$M$5:$M$304,0),"") | AD14: =IFERROR(MATCH(TEXT(D$10,"yyyymmdd")&"|"&$A14,Events!$M$5:$M$304,0),"") | AE14: =IFERROR(MATCH(TEXT(F$10,"yyyymmdd")&"|"&$A14,Events!$M$5:$M$304,0),"") -> 28 | AF14: =IFERROR(MATCH(TEXT(H$10,"yyyymmdd")&"|"&$A14,Events!$M$5:$M$304,0),"") -> 36 | AG14: =IFERROR(MATCH(TEXT(J$10,"yyyymmdd")&"|"&$A14,Events!$M$5:$M$304,0),"")
A15: 5 | B15: =IF($AC15="","",IFERROR(INDEX({"CB","SPK","GOV","INF","JOB","BIZ","HOL"},MATCH(INDEX(Events!$E$5:$E$304,$AC15),{"Central bank","CB speech","Government","Inflation","Jobs","Growth & business","Holiday"},0)),"?")) | C15: =IF($AC15="","",IF(INDEX(Events!$D$5:$D$304,$AC15)="High","● ",IF(INDEX(Events!$D$5:$D$304,$AC15)="Medium","○ "," "))&IF(INDEX(Events!$B$5:$B$304,$AC15)="","all day",TEXT(INDEX(Events!$B$5:$B$304,$AC15),"hh:mm"))&" "&INDEX(Events!$C$5:$C$304,$AC15)&" "&INDEX(Events!$F$5:$F$304,$AC15)) | D15: =IF($AD15="","",IFERROR(INDEX({"CB","SPK","GOV","INF","JOB","BIZ","HOL"},MATCH(INDEX(Events!$E$5:$E$304,$AD15),{"Central bank","CB speech","Government","Inflation","Jobs","Growth & business","Holiday"},0)),"?")) | E15: =IF($AD15="","",IF(INDEX(Events!$D$5:$D$304,$AD15)="High","● ",IF(INDEX(Events!$D$5:$D$304,$AD15)="Medium","○ "," "))&IF(INDEX(Events!$B$5:$B$304,$AD15)="","all day",TEXT(INDEX(Events!$B$5:$B$304,$AD15),"hh:mm"))&" "&INDEX(Events!$C$5:$C$304,$AD15)&" "&INDEX(Events!$F$5:$F$304,$AD15)) | F15: =IF($AE15="","",IFERROR(INDEX({"CB","SPK","GOV","INF","JOB","BIZ","HOL"},MATCH(INDEX(Events!$E$5:$E$304,$AE15),{"Central bank","CB speech","Government","Inflation","Jobs","Growth & business","Holiday"},0)),"?")) -> INF | G15: =IF($AE15="","",IF(INDEX(Events!$D$5:$D$304,$AE15)="High","● ",IF(INDEX(Events!$D$5:$D$304,$AE15)="Medium","○ "," "))&IF(INDEX(Events!$B$5:$B$304,$AE15)="","all day",TEXT(INDEX(Events!$B$5:$B$304,$AE15),"hh:mm"))&" "&INDEX(Events!$C$5:$C$304,$AE15)&" "&INDEX(Events!$F$5:$F$304,$AE15)) -> ● 14:30 USD Core CPI m/m | H15: =IF($AF15="","",IFERROR(INDEX({"CB","SPK","GOV","INF","JOB","BIZ","HOL"},MATCH(INDEX(Events!$E$5:$E$304,$AF15),{"Central bank","CB speech","Government","Inflation","Jobs","Growth & business","Holiday"},0)),"?")) -> GOV | I15: =IF($AF15="","",IF(INDEX(Events!$D$5:$D$304,$AF15)="High","● ",IF(INDEX(Events!$D$5:$D$304,$AF15)="Medium","○ "," "))&IF(INDEX(Events!$B$5:$B$304,$AF15)="","all day",TEXT(INDEX(Events!$B$5:$B$304,$AF15),"hh:mm"))&" "&INDEX(Events!$C$5:$C$304,$AF15)&" "&INDEX(Events!$F$5:$F$304,$AF15)) -> ○ 12:15 EUR EU Economic Summit | J15: =IF($AG15="","",IFERROR(INDEX({"CB","SPK","GOV","INF","JOB","BIZ","HOL"},MATCH(INDEX(Events!$E$5:$E$304,$AG15),{"Central bank","CB speech","Government","Inflation","Jobs","Growth & business","Holiday"},0)),"?")) | K15: =IF($AG15="","",IF(INDEX(Events!$D$5:$D$304,$AG15)="High","● ",IF(INDEX(Events!$D$5:$D$304,$AG15)="Medium","○ "," "))&IF(INDEX(Events!$B$5:$B$304,$AG15)="","all day",TEXT(INDEX(Events!$B$5:$B$304,$AG15),"hh:mm"))&" "&INDEX(Events!$C$5:$C$304,$AG15)&" "&INDEX(Events!$F$5:$F$304,$AG15)) | M15: =(DATE(YEAR($H$6),MONTH($H$6),1)-WEEKDAY(DATE(YEAR($H$6),MONTH($H$6),1),3))+21 -> 46314 | N15: =(DATE(YEAR($H$6),MONTH($H$6),1)-WEEKDAY(DATE(YEAR($H$6),MONTH($H$6),1),3))+22 -> 46315 | O15: =(DATE(YEAR($H$6),MONTH($H$6),1)-WEEKDAY(DATE(YEAR($H$6),MONTH($H$6),1),3))+23 -> 46316 | P15: =(DATE(YEAR($H$6),MONTH($H$6),1)-WEEKDAY(DATE(YEAR($H$6),MONTH($H$6),1),3))+24 -> 46317 | Q15: =(DATE(YEAR($H$6),MONTH($H$6),1)-WEEKDAY(DATE(YEAR($H$6),MONTH($H$6),1),3))+25 -> 46318 | R15: =(DATE(YEAR($H$6),MONTH($H$6),1)-WEEKDAY(DATE(YEAR($H$6),MONTH($H$6),1),3))+26 -> 46319 | S15: =(DATE(YEAR($H$6),MONTH($H$6),1)-WEEKDAY(DATE(YEAR($H$6),MONTH($H$6),1),3))+27 -> 46320 | U15: =(EDATE(DATE(YEAR($H$6),MONTH($H$6),1),1)-WEEKDAY(EDATE(DATE(YEAR($H$6),MONTH($H$6),1),1),3))+21 -> 46342 | V15: =(EDATE(DATE(YEAR($H$6),MONTH($H$6),1),1)-WEEKDAY(EDATE(DATE(YEAR($H$6),MONTH($H$6),1),1),3))+22 -> 46343 | W15: =(EDATE(DATE(YEAR($H$6),MONTH($H$6),1),1)-WEEKDAY(EDATE(DATE(YEAR($H$6),MONTH($H$6),1),1),3))+23 -> 46344 | X15: =(EDATE(DATE(YEAR($H$6),MONTH($H$6),1),1)-WEEKDAY(EDATE(DATE(YEAR($H$6),MONTH($H$6),1),1),3))+24 -> 46345 | Y15: =(EDATE(DATE(YEAR($H$6),MONTH($H$6),1),1)-WEEKDAY(EDATE(DATE(YEAR($H$6),MONTH($H$6),1),1),3))+25 -> 46346 | Z15: =(EDATE(DATE(YEAR($H$6),MONTH($H$6),1),1)-WEEKDAY(EDATE(DATE(YEAR($H$6),MONTH($H$6),1),1),3))+26 -> 46347 | AA15: =(EDATE(DATE(YEAR($H$6),MONTH($H$6),1),1)-WEEKDAY(EDATE(DATE(YEAR($H$6),MONTH($H$6),1),1),3))+27 -> 46348 | AC15: =IFERROR(MATCH(TEXT(B$10,"yyyymmdd")&"|"&$A15,Events!$M$5:$M$304,0),"") | AD15: =IFERROR(MATCH(TEXT(D$10,"yyyymmdd")&"|"&$A15,Events!$M$5:$M$304,0),"") | AE15: =IFERROR(MATCH(TEXT(F$10,"yyyymmdd")&"|"&$A15,Events!$M$5:$M$304,0),"") -> 29 | AF15: =IFERROR(MATCH(TEXT(H$10,"yyyymmdd")&"|"&$A15,Events!$M$5:$M$304,0),"") -> 37 | AG15: =IFERROR(MATCH(TEXT(J$10,"yyyymmdd")&"|"&$A15,Events!$M$5:$M$304,0),"")
A16: 6 | B16: =IF($AC16="","",IFERROR(INDEX({"CB","SPK","GOV","INF","JOB","BIZ","HOL"},MATCH(INDEX(Events!$E$5:$E$304,$AC16),{"Central bank","CB speech","Government","Inflation","Jobs","Growth & business","Holiday"},0)),"?")) | C16: =IF($AC16="","",IF(INDEX(Events!$D$5:$D$304,$AC16)="High","● ",IF(INDEX(Events!$D$5:$D$304,$AC16)="Medium","○ "," "))&IF(INDEX(Events!$B$5:$B$304,$AC16)="","all day",TEXT(INDEX(Events!$B$5:$B$304,$AC16),"hh:mm"))&" "&INDEX(Events!$C$5:$C$304,$AC16)&" "&INDEX(Events!$F$5:$F$304,$AC16)) | D16: =IF($AD16="","",IFERROR(INDEX({"CB","SPK","GOV","INF","JOB","BIZ","HOL"},MATCH(INDEX(Events!$E$5:$E$304,$AD16),{"Central bank","CB speech","Government","Inflation","Jobs","Growth & business","Holiday"},0)),"?")) | E16: =IF($AD16="","",IF(INDEX(Events!$D$5:$D$304,$AD16)="High","● ",IF(INDEX(Events!$D$5:$D$304,$AD16)="Medium","○ "," "))&IF(INDEX(Events!$B$5:$B$304,$AD16)="","all day",TEXT(INDEX(Events!$B$5:$B$304,$AD16),"hh:mm"))&" "&INDEX(Events!$C$5:$C$304,$AD16)&" "&INDEX(Events!$F$5:$F$304,$AD16)) | F16: =IF($AE16="","",IFERROR(INDEX({"CB","SPK","GOV","INF","JOB","BIZ","HOL"},MATCH(INDEX(Events!$E$5:$E$304,$AE16),{"Central bank","CB speech","Government","Inflation","Jobs","Growth & business","Holiday"},0)),"?")) -> INF | G16: =IF($AE16="","",IF(INDEX(Events!$D$5:$D$304,$AE16)="High","● ",IF(INDEX(Events!$D$5:$D$304,$AE16)="Medium","○ "," "))&IF(INDEX(Events!$B$5:$B$304,$AE16)="","all day",TEXT(INDEX(Events!$B$5:$B$304,$AE16),"hh:mm"))&" "&INDEX(Events!$C$5:$C$304,$AE16)&" "&INDEX(Events!$F$5:$F$304,$AE16)) -> ● 14:30 USD Core CPI y/y | H16: =IF($AF16="","",IFERROR(INDEX({"CB","SPK","GOV","INF","JOB","BIZ","HOL"},MATCH(INDEX(Events!$E$5:$E$304,$AF16),{"Central bank","CB speech","Government","Inflation","Jobs","Growth & business","Holiday"},0)),"?")) -> INF | I16: =IF($AF16="","",IF(INDEX(Events!$D$5:$D$304,$AF16)="High","● ",IF(INDEX(Events!$D$5:$D$304,$AF16)="Medium","○ "," "))&IF(INDEX(Events!$B$5:$B$304,$AF16)="","all day",TEXT(INDEX(Events!$B$5:$B$304,$AF16),"hh:mm"))&" "&INDEX(Events!$C$5:$C$304,$AF16)&" "&INDEX(Events!$F$5:$F$304,$AF16)) -> ● 14:30 USD Core PPI m/m | J16: =IF($AG16="","",IFERROR(INDEX({"CB","SPK","GOV","INF","JOB","BIZ","HOL"},MATCH(INDEX(Events!$E$5:$E$304,$AG16),{"Central bank","CB speech","Government","Inflation","Jobs","Growth & business","Holiday"},0)),"?")) | K16: =IF($AG16="","",IF(INDEX(Events!$D$5:$D$304,$AG16)="High","● ",IF(INDEX(Events!$D$5:$D$304,$AG16)="Medium","○ "," "))&IF(INDEX(Events!$B$5:$B$304,$AG16)="","all day",TEXT(INDEX(Events!$B$5:$B$304,$AG16),"hh:mm"))&" "&INDEX(Events!$C$5:$C$304,$AG16)&" "&INDEX(Events!$F$5:$F$304,$AG16)) | M16: =(DATE(YEAR($H$6),MONTH($H$6),1)-WEEKDAY(DATE(YEAR($H$6),MONTH($H$6),1),3))+28 -> 46321 | N16: =(DATE(YEAR($H$6),MONTH($H$6),1)-WEEKDAY(DATE(YEAR($H$6),MONTH($H$6),1),3))+29 -> 46322 | O16: =(DATE(YEAR($H$6),MONTH($H$6),1)-WEEKDAY(DATE(YEAR($H$6),MONTH($H$6),1),3))+30 -> 46323 | P16: =(DATE(YEAR($H$6),MONTH($H$6),1)-WEEKDAY(DATE(YEAR($H$6),MONTH($H$6),1),3))+31 -> 46324 | Q16: =(DATE(YEAR($H$6),MONTH($H$6),1)-WEEKDAY(DATE(YEAR($H$6),MONTH($H$6),1),3))+32 -> 46325 | R16: =(DATE(YEAR($H$6),MONTH($H$6),1)-WEEKDAY(DATE(YEAR($H$6),MONTH($H$6),1),3))+33 -> 46326 | S16: =(DATE(YEAR($H$6),MONTH($H$6),1)-WEEKDAY(DATE(YEAR($H$6),MONTH($H$6),1),3))+34 -> 46327 | U16: =(EDATE(DATE(YEAR($H$6),MONTH($H$6),1),1)-WEEKDAY(EDATE(DATE(YEAR($H$6),MONTH($H$6),1),1),3))+28 -> 46349 | V16: =(EDATE(DATE(YEAR($H$6),MONTH($H$6),1),1)-WEEKDAY(EDATE(DATE(YEAR($H$6),MONTH($H$6),1),1),3))+29 -> 46350 | W16: =(EDATE(DATE(YEAR($H$6),MONTH($H$6),1),1)-WEEKDAY(EDATE(DATE(YEAR($H$6),MONTH($H$6),1),1),3))+30 -> 46351 | X16: =(EDATE(DATE(YEAR($H$6),MONTH($H$6),1),1)-WEEKDAY(EDATE(DATE(YEAR($H$6),MONTH($H$6),1),1),3))+31 -> 46352 | Y16: =(EDATE(DATE(YEAR($H$6),MONTH($H$6),1),1)-WEEKDAY(EDATE(DATE(YEAR($H$6),MONTH($H$6),1),1),3))+32 -> 46353 | Z16: =(EDATE(DATE(YEAR($H$6),MONTH($H$6),1),1)-WEEKDAY(EDATE(DATE(YEAR($H$6),MONTH($H$6),1),1),3))+33 -> 46354 | AA16: =(EDATE(DATE(YEAR($H$6),MONTH($H$6),1),1)-WEEKDAY(EDATE(DATE(YEAR($H$6),MONTH($H$6),1),1),3))+34 -> 46355 | AC16: =IFERROR(MATCH(TEXT(B$10,"yyyymmdd")&"|"&$A16,Events!$M$5:$M$304,0),"") | AD16: =IFERROR(MATCH(TEXT(D$10,"yyyymmdd")&"|"&$A16,Events!$M$5:$M$304,0),"") | AE16: =IFERROR(MATCH(TEXT(F$10,"yyyymmdd")&"|"&$A16,Events!$M$5:$M$304,0),"") -> 30 | AF16: =IFERROR(MATCH(TEXT(H$10,"yyyymmdd")&"|"&$A16,Events!$M$5:$M$304,0),"") -> 38 | AG16: =IFERROR(MATCH(TEXT(J$10,"yyyymmdd")&"|"&$A16,Events!$M$5:$M$304,0),"")
A17: 7 | B17: =IF($AC17="","",IFERROR(INDEX({"CB","SPK","GOV","INF","JOB","BIZ","HOL"},MATCH(INDEX(Events!$E$5:$E$304,$AC17),{"Central bank","CB speech","Government","Inflation","Jobs","Growth & business","Holiday"},0)),"?")) | C17: =IF($AC17="","",IF(INDEX(Events!$D$5:$D$304,$AC17)="High","● ",IF(INDEX(Events!$D$5:$D$304,$AC17)="Medium","○ "," "))&IF(INDEX(Events!$B$5:$B$304,$AC17)="","all day",TEXT(INDEX(Events!$B$5:$B$304,$AC17),"hh:mm"))&" "&INDEX(Events!$C$5:$C$304,$AC17)&" "&INDEX(Events!$F$5:$F$304,$AC17)) | D17: =IF($AD17="","",IFERROR(INDEX({"CB","SPK","GOV","INF","JOB","BIZ","HOL"},MATCH(INDEX(Events!$E$5:$E$304,$AD17),{"Central bank","CB speech","Government","Inflation","Jobs","Growth & business","Holiday"},0)),"?")) | E17: =IF($AD17="","",IF(INDEX(Events!$D$5:$D$304,$AD17)="High","● ",IF(INDEX(Events!$D$5:$D$304,$AD17)="Medium","○ "," "))&IF(INDEX(Events!$B$5:$B$304,$AD17)="","all day",TEXT(INDEX(Events!$B$5:$B$304,$AD17),"hh:mm"))&" "&INDEX(Events!$C$5:$C$304,$AD17)&" "&INDEX(Events!$F$5:$F$304,$AD17)) | F17: =IF($AE17="","",IFERROR(INDEX({"CB","SPK","GOV","INF","JOB","BIZ","HOL"},MATCH(INDEX(Events!$E$5:$E$304,$AE17),{"Central bank","CB speech","Government","Inflation","Jobs","Growth & business","Holiday"},0)),"?")) -> INF | G17: =IF($AE17="","",IF(INDEX(Events!$D$5:$D$304,$AE17)="High","● ",IF(INDEX(Events!$D$5:$D$304,$AE17)="Medium","○ "," "))&IF(INDEX(Events!$B$5:$B$304,$AE17)="","all day",TEXT(INDEX(Events!$B$5:$B$304,$AE17),"hh:mm"))&" "&INDEX(Events!$C$5:$C$304,$AE17)&" "&INDEX(Events!$F$5:$F$304,$AE17)) -> ● 14:30 USD CPI m/m | H17: =IF($AF17="","",IFERROR(INDEX({"CB","SPK","GOV","INF","JOB","BIZ","HOL"},MATCH(INDEX(Events!$E$5:$E$304,$AF17),{"Central bank","CB speech","Government","Inflation","Jobs","Growth & business","Holiday"},0)),"?")) -> BIZ | I17: =IF($AF17="","",IF(INDEX(Events!$D$5:$D$304,$AF17)="High","● ",IF(INDEX(Events!$D$5:$D$304,$AF17)="Medium","○ "," "))&IF(INDEX(Events!$B$5:$B$304,$AF17)="","all day",TEXT(INDEX(Events!$B$5:$B$304,$AF17),"hh:mm"))&" "&INDEX(Events!$C$5:$C$304,$AF17)&" "&INDEX(Events!$F$5:$F$304,$AF17)) -> ● 14:30 USD Core Retail Sales m/m | J17: =IF($AG17="","",IFERROR(INDEX({"CB","SPK","GOV","INF","JOB","BIZ","HOL"},MATCH(INDEX(Events!$E$5:$E$304,$AG17),{"Central bank","CB speech","Government","Inflation","Jobs","Growth & business","Holiday"},0)),"?")) | K17: =IF($AG17="","",IF(INDEX(Events!$D$5:$D$304,$AG17)="High","● ",IF(INDEX(Events!$D$5:$D$304,$AG17)="Medium","○ "," "))&IF(INDEX(Events!$B$5:$B$304,$AG17)="","all day",TEXT(INDEX(Events!$B$5:$B$304,$AG17),"hh:mm"))&" "&INDEX(Events!$C$5:$C$304,$AG17)&" "&INDEX(Events!$F$5:$F$304,$AG17)) | M17: =(DATE(YEAR($H$6),MONTH($H$6),1)-WEEKDAY(DATE(YEAR($H$6),MONTH($H$6),1),3))+35 -> 46328 | N17: =(DATE(YEAR($H$6),MONTH($H$6),1)-WEEKDAY(DATE(YEAR($H$6),MONTH($H$6),1),3))+36 -> 46329 | O17: =(DATE(YEAR($H$6),MONTH($H$6),1)-WEEKDAY(DATE(YEAR($H$6),MONTH($H$6),1),3))+37 -> 46330 | P17: =(DATE(YEAR($H$6),MONTH($H$6),1)-WEEKDAY(DATE(YEAR($H$6),MONTH($H$6),1),3))+38 -> 46331 | Q17: =(DATE(YEAR($H$6),MONTH($H$6),1)-WEEKDAY(DATE(YEAR($H$6),MONTH($H$6),1),3))+39 -> 46332 | R17: =(DATE(YEAR($H$6),MONTH($H$6),1)-WEEKDAY(DATE(YEAR($H$6),MONTH($H$6),1),3))+40 -> 46333 | S17: =(DATE(YEAR($H$6),MONTH($H$6),1)-WEEKDAY(DATE(YEAR($H$6),MONTH($H$6),1),3))+41 -> 46334 | U17: =(EDATE(DATE(YEAR($H$6),MONTH($H$6),1),1)-WEEKDAY(EDATE(DATE(YEAR($H$6),MONTH($H$6),1),1),3))+35 -> 46356 | V17: =(EDATE(DATE(YEAR($H$6),MONTH($H$6),1),1)-WEEKDAY(EDATE(DATE(YEAR($H$6),MONTH($H$6),1),1),3))+36 -> 46357 | W17: =(EDATE(DATE(YEAR($H$6),MONTH($H$6),1),1)-WEEKDAY(EDATE(DATE(YEAR($H$6),MONTH($H$6),1),1),3))+37 -> 46358 | X17: =(EDATE(DATE(YEAR($H$6),MONTH($H$6),1),1)-WEEKDAY(EDATE(DATE(YEAR($H$6),MONTH($H$6),1),1),3))+38 -> 46359 | Y17: =(EDATE(DATE(YEAR($H$6),MONTH($H$6),1),1)-WEEKDAY(EDATE(DATE(YEAR($H$6),MONTH($H$6),1),1),3))+39 -> 46360 | Z17: =(EDATE(DATE(YEAR($H$6),MONTH($H$6),1),1)-WEEKDAY(EDATE(DATE(YEAR($H$6),MONTH($H$6),1),1),3))+40 -> 46361 | AA17: =(EDATE(DATE(YEAR($H$6),MONTH($H$6),1),1)-WEEKDAY(EDATE(DATE(YEAR($H$6),MONTH($H$6),1),1),3))+41 -> 46362 | AC17: =IFERROR(MATCH(TEXT(B$10,"yyyymmdd")&"|"&$A17,Events!$M$5:$M$304,0),"") | AD17: =IFERROR(MATCH(TEXT(D$10,"yyyymmdd")&"|"&$A17,Events!$M$5:$M$304,0),"") | AE17: =IFERROR(MATCH(TEXT(F$10,"yyyymmdd")&"|"&$A17,Events!$M$5:$M$304,0),"") -> 31 | AF17: =IFERROR(MATCH(TEXT(H$10,"yyyymmdd")&"|"&$A17,Events!$M$5:$M$304,0),"") -> 39 | AG17: =IFERROR(MATCH(TEXT(J$10,"yyyymmdd")&"|"&$A17,Events!$M$5:$M$304,0),"")
A18: 8 | B18: =IF($AC18="","",IFERROR(INDEX({"CB","SPK","GOV","INF","JOB","BIZ","HOL"},MATCH(INDEX(Events!$E$5:$E$304,$AC18),{"Central bank","CB speech","Government","Inflation","Jobs","Growth & business","Holiday"},0)),"?")) | C18: =IF($AC18="","",IF(INDEX(Events!$D$5:$D$304,$AC18)="High","● ",IF(INDEX(Events!$D$5:$D$304,$AC18)="Medium","○ "," "))&IF(INDEX(Events!$B$5:$B$304,$AC18)="","all day",TEXT(INDEX(Events!$B$5:$B$304,$AC18),"hh:mm"))&" "&INDEX(Events!$C$5:$C$304,$AC18)&" "&INDEX(Events!$F$5:$F$304,$AC18)) | D18: =IF($AD18="","",IFERROR(INDEX({"CB","SPK","GOV","INF","JOB","BIZ","HOL"},MATCH(INDEX(Events!$E$5:$E$304,$AD18),{"Central bank","CB speech","Government","Inflation","Jobs","Growth & business","Holiday"},0)),"?")) | E18: =IF($AD18="","",IF(INDEX(Events!$D$5:$D$304,$AD18)="High","● ",IF(INDEX(Events!$D$5:$D$304,$AD18)="Medium","○ "," "))&IF(INDEX(Events!$B$5:$B$304,$AD18)="","all day",TEXT(INDEX(Events!$B$5:$B$304,$AD18),"hh:mm"))&" "&INDEX(Events!$C$5:$C$304,$AD18)&" "&INDEX(Events!$F$5:$F$304,$AD18)) | F18: =IF($AE18="","",IFERROR(INDEX({"CB","SPK","GOV","INF","JOB","BIZ","HOL"},MATCH(INDEX(Events!$E$5:$E$304,$AE18),{"Central bank","CB speech","Government","Inflation","Jobs","Growth & business","Holiday"},0)),"?")) -> INF | G18: =IF($AE18="","",IF(INDEX(Events!$D$5:$D$304,$AE18)="High","● ",IF(INDEX(Events!$D$5:$D$304,$AE18)="Medium","○ "," "))&IF(INDEX(Events!$B$5:$B$304,$AE18)="","all day",TEXT(INDEX(Events!$B$5:$B$304,$AE18),"hh:mm"))&" "&INDEX(Events!$C$5:$C$304,$AE18)&" "&INDEX(Events!$F$5:$F$304,$AE18)) -> ● 14:30 USD CPI y/y | H18: =IF($AF18="","",IFERROR(INDEX({"CB","SPK","GOV","INF","JOB","BIZ","HOL"},MATCH(INDEX(Events!$E$5:$E$304,$AF18),{"Central bank","CB speech","Government","Inflation","Jobs","Growth & business","Holiday"},0)),"?")) -> INF | I18: =IF($AF18="","",IF(INDEX(Events!$D$5:$D$304,$AF18)="High","● ",IF(INDEX(Events!$D$5:$D$304,$AF18)="Medium","○ "," "))&IF(INDEX(Events!$B$5:$B$304,$AF18)="","all day",TEXT(INDEX(Events!$B$5:$B$304,$AF18),"hh:mm"))&" "&INDEX(Events!$C$5:$C$304,$AF18)&" "&INDEX(Events!$F$5:$F$304,$AF18)) -> ● 14:30 USD PPI m/m | J18: =IF($AG18="","",IFERROR(INDEX({"CB","SPK","GOV","INF","JOB","BIZ","HOL"},MATCH(INDEX(Events!$E$5:$E$304,$AG18),{"Central bank","CB speech","Government","Inflation","Jobs","Growth & business","Holiday"},0)),"?")) | K18: =IF($AG18="","",IF(INDEX(Events!$D$5:$D$304,$AG18)="High","● ",IF(INDEX(Events!$D$5:$D$304,$AG18)="Medium","○ "," "))&IF(INDEX(Events!$B$5:$B$304,$AG18)="","all day",TEXT(INDEX(Events!$B$5:$B$304,$AG18),"hh:mm"))&" "&INDEX(Events!$C$5:$C$304,$AG18)&" "&INDEX(Events!$F$5:$F$304,$AG18)) | AC18: =IFERROR(MATCH(TEXT(B$10,"yyyymmdd")&"|"&$A18,Events!$M$5:$M$304,0),"") | AD18: =IFERROR(MATCH(TEXT(D$10,"yyyymmdd")&"|"&$A18,Events!$M$5:$M$304,0),"") | AE18: =IFERROR(MATCH(TEXT(F$10,"yyyymmdd")&"|"&$A18,Events!$M$5:$M$304,0),"") -> 32 | AF18: =IFERROR(MATCH(TEXT(H$10,"yyyymmdd")&"|"&$A18,Events!$M$5:$M$304,0),"") -> 40 | AG18: =IFERROR(MATCH(TEXT(J$10,"yyyymmdd")&"|"&$A18,Events!$M$5:$M$304,0),"")
A19: 9 | B19: =IF($AC19="","",IFERROR(INDEX({"CB","SPK","GOV","INF","JOB","BIZ","HOL"},MATCH(INDEX(Events!$E$5:$E$304,$AC19),{"Central bank","CB speech","Government","Inflation","Jobs","Growth & business","Holiday"},0)),"?")) | C19: =IF($AC19="","",IF(INDEX(Events!$D$5:$D$304,$AC19)="High","● ",IF(INDEX(Events!$D$5:$D$304,$AC19)="Medium","○ "," "))&IF(INDEX(Events!$B$5:$B$304,$AC19)="","all day",TEXT(INDEX(Events!$B$5:$B$304,$AC19),"hh:mm"))&" "&INDEX(Events!$C$5:$C$304,$AC19)&" "&INDEX(Events!$F$5:$F$304,$AC19)) | D19: =IF($AD19="","",IFERROR(INDEX({"CB","SPK","GOV","INF","JOB","BIZ","HOL"},MATCH(INDEX(Events!$E$5:$E$304,$AD19),{"Central bank","CB speech","Government","Inflation","Jobs","Growth & business","Holiday"},0)),"?")) | E19: =IF($AD19="","",IF(INDEX(Events!$D$5:$D$304,$AD19)="High","● ",IF(INDEX(Events!$D$5:$D$304,$AD19)="Medium","○ "," "))&IF(INDEX(Events!$B$5:$B$304,$AD19)="","all day",TEXT(INDEX(Events!$B$5:$B$304,$AD19),"hh:mm"))&" "&INDEX(Events!$C$5:$C$304,$AD19)&" "&INDEX(Events!$F$5:$F$304,$AD19)) | F19: =IF($AE19="","",IFERROR(INDEX({"CB","SPK","GOV","INF","JOB","BIZ","HOL"},MATCH(INDEX(Events!$E$5:$E$304,$AE19),{"Central bank","CB speech","Government","Inflation","Jobs","Growth & business","Holiday"},0)),"?")) | G19: =IF($AE19="","",IF(INDEX(Events!$D$5:$D$304,$AE19)="High","● ",IF(INDEX(Events!$D$5:$D$304,$AE19)="Medium","○ "," "))&IF(INDEX(Events!$B$5:$B$304,$AE19)="","all day",TEXT(INDEX(Events!$B$5:$B$304,$AE19),"hh:mm"))&" "&INDEX(Events!$C$5:$C$304,$AE19)&" "&INDEX(Events!$F$5:$F$304,$AE19)) | H19: =IF($AF19="","",IFERROR(INDEX({"CB","SPK","GOV","INF","JOB","BIZ","HOL"},MATCH(INDEX(Events!$E$5:$E$304,$AF19),{"Central bank","CB speech","Government","Inflation","Jobs","Growth & business","Holiday"},0)),"?")) -> BIZ | I19: =IF($AF19="","",IF(INDEX(Events!$D$5:$D$304,$AF19)="High","● ",IF(INDEX(Events!$D$5:$D$304,$AF19)="Medium","○ "," "))&IF(INDEX(Events!$B$5:$B$304,$AF19)="","all day",TEXT(INDEX(Events!$B$5:$B$304,$AF19),"hh:mm"))&" "&INDEX(Events!$C$5:$C$304,$AF19)&" "&INDEX(Events!$F$5:$F$304,$AF19)) -> ● 14:30 USD Retail Sales m/m | J19: =IF($AG19="","",IFERROR(INDEX({"CB","SPK","GOV","INF","JOB","BIZ","HOL"},MATCH(INDEX(Events!$E$5:$E$304,$AG19),{"Central bank","CB speech","Government","Inflation","Jobs","Growth & business","Holiday"},0)),"?")) | K19: =IF($AG19="","",IF(INDEX(Events!$D$5:$D$304,$AG19)="High","● ",IF(INDEX(Events!$D$5:$D$304,$AG19)="Medium","○ "," "))&IF(INDEX(Events!$B$5:$B$304,$AG19)="","all day",TEXT(INDEX(Events!$B$5:$B$304,$AG19),"hh:mm"))&" "&INDEX(Events!$C$5:$C$304,$AG19)&" "&INDEX(Events!$F$5:$F$304,$AG19)) | M19: =TEXT(EDATE(DATE(YEAR($H$6),MONTH($H$6),1),2),"mmmm yyyy") -> December 2026 | U19: =TEXT(EDATE(DATE(YEAR($H$6),MONTH($H$6),1),3),"mmmm yyyy") -> January 2027 | AC19: =IFERROR(MATCH(TEXT(B$10,"yyyymmdd")&"|"&$A19,Events!$M$5:$M$304,0),"") | AD19: =IFERROR(MATCH(TEXT(D$10,"yyyymmdd")&"|"&$A19,Events!$M$5:$M$304,0),"") | AE19: =IFERROR(MATCH(TEXT(F$10,"yyyymmdd")&"|"&$A19,Events!$M$5:$M$304,0),"") | AF19: =IFERROR(MATCH(TEXT(H$10,"yyyymmdd")&"|"&$A19,Events!$M$5:$M$304,0),"") -> 41 | AG19: =IFERROR(MATCH(TEXT(J$10,"yyyymmdd")&"|"&$A19,Events!$M$5:$M$304,0),"")
A20: 10 | B20: =IF($AC20="","",IFERROR(INDEX({"CB","SPK","GOV","INF","JOB","BIZ","HOL"},MATCH(INDEX(Events!$E$5:$E$304,$AC20),{"Central bank","CB speech","Government","Inflation","Jobs","Growth & business","Holiday"},0)),"?")) | C20: =IF($AC20="","",IF(INDEX(Events!$D$5:$D$304,$AC20)="High","● ",IF(INDEX(Events!$D$5:$D$304,$AC20)="Medium","○ "," "))&IF(INDEX(Events!$B$5:$B$304,$AC20)="","all day",TEXT(INDEX(Events!$B$5:$B$304,$AC20),"hh:mm"))&" "&INDEX(Events!$C$5:$C$304,$AC20)&" "&INDEX(Events!$F$5:$F$304,$AC20)) | D20: =IF($AD20="","",IFERROR(INDEX({"CB","SPK","GOV","INF","JOB","BIZ","HOL"},MATCH(INDEX(Events!$E$5:$E$304,$AD20),{"Central bank","CB speech","Government","Inflation","Jobs","Growth & business","Holiday"},0)),"?")) | E20: =IF($AD20="","",IF(INDEX(Events!$D$5:$D$304,$AD20)="High","● ",IF(INDEX(Events!$D$5:$D$304,$AD20)="Medium","○ "," "))&IF(INDEX(Events!$B$5:$B$304,$AD20)="","all day",TEXT(INDEX(Events!$B$5:$B$304,$AD20),"hh:mm"))&" "&INDEX(Events!$C$5:$C$304,$AD20)&" "&INDEX(Events!$F$5:$F$304,$AD20)) | F20: =IF($AE20="","",IFERROR(INDEX({"CB","SPK","GOV","INF","JOB","BIZ","HOL"},MATCH(INDEX(Events!$E$5:$E$304,$AE20),{"Central bank","CB speech","Government","Inflation","Jobs","Growth & business","Holiday"},0)),"?")) | G20: =IF($AE20="","",IF(INDEX(Events!$D$5:$D$304,$AE20)="High","● ",IF(INDEX(Events!$D$5:$D$304,$AE20)="Medium","○ "," "))&IF(INDEX(Events!$B$5:$B$304,$AE20)="","all day",TEXT(INDEX(Events!$B$5:$B$304,$AE20),"hh:mm"))&" "&INDEX(Events!$C$5:$C$304,$AE20)&" "&INDEX(Events!$F$5:$F$304,$AE20)) | H20: =IF($AF20="","",IFERROR(INDEX({"CB","SPK","GOV","INF","JOB","BIZ","HOL"},MATCH(INDEX(Events!$E$5:$E$304,$AF20),{"Central bank","CB speech","Government","Inflation","Jobs","Growth & business","Holiday"},0)),"?")) -> BIZ | I20: =IF($AF20="","",IF(INDEX(Events!$D$5:$D$304,$AF20)="High","● ",IF(INDEX(Events!$D$5:$D$304,$AF20)="Medium","○ "," "))&IF(INDEX(Events!$B$5:$B$304,$AF20)="","all day",TEXT(INDEX(Events!$B$5:$B$304,$AF20),"hh:mm"))&" "&INDEX(Events!$C$5:$C$304,$AF20)&" "&INDEX(Events!$F$5:$F$304,$AF20)) -> ○ 14:30 USD Philly Fed Manufacturing Index | J20: =IF($AG20="","",IFERROR(INDEX({"CB","SPK","GOV","INF","JOB","BIZ","HOL"},MATCH(INDEX(Events!$E$5:$E$304,$AG20),{"Central bank","CB speech","Government","Inflation","Jobs","Growth & business","Holiday"},0)),"?")) | K20: =IF($AG20="","",IF(INDEX(Events!$D$5:$D$304,$AG20)="High","● ",IF(INDEX(Events!$D$5:$D$304,$AG20)="Medium","○ "," "))&IF(INDEX(Events!$B$5:$B$304,$AG20)="","all day",TEXT(INDEX(Events!$B$5:$B$304,$AG20),"hh:mm"))&" "&INDEX(Events!$C$5:$C$304,$AG20)&" "&INDEX(Events!$F$5:$F$304,$AG20)) | M20: Mo | N20: Tu | O20: We | P20: Th | Q20: Fr | R20: Sa | S20: Su | U20: Mo | V20: Tu | W20: We | X20: Th | Y20: Fr | Z20: Sa | AA20: Su | AC20: =IFERROR(MATCH(TEXT(B$10,"yyyymmdd")&"|"&$A20,Events!$M$5:$M$304,0),"") | AD20: =IFERROR(MATCH(TEXT(D$10,"yyyymmdd")&"|"&$A20,Events!$M$5:$M$304,0),"") | AE20: =IFERROR(MATCH(TEXT(F$10,"yyyymmdd")&"|"&$A20,Events!$M$5:$M$304,0),"") | AF20: =IFERROR(MATCH(TEXT(H$10,"yyyymmdd")&"|"&$A20,Events!$M$5:$M$304,0),"") -> 42 | AG20: =IFERROR(MATCH(TEXT(J$10,"yyyymmdd")&"|"&$A20,Events!$M$5:$M$304,0),"")
A21: 11 | B21: =IF($AC21="","",IFERROR(INDEX({"CB","SPK","GOV","INF","JOB","BIZ","HOL"},MATCH(INDEX(Events!$E$5:$E$304,$AC21),{"Central bank","CB speech","Government","Inflation","Jobs","Growth & business","Holiday"},0)),"?")) | C21: =IF($AC21="","",IF(INDEX(Events!$D$5:$D$304,$AC21)="High","● ",IF(INDEX(Events!$D$5:$D$304,$AC21)="Medium","○ "," "))&IF(INDEX(Events!$B$5:$B$304,$AC21)="","all day",TEXT(INDEX(Events!$B$5:$B$304,$AC21),"hh:mm"))&" "&INDEX(Events!$C$5:$C$304,$AC21)&" "&INDEX(Events!$F$5:$F$304,$AC21)) | D21: =IF($AD21="","",IFERROR(INDEX({"CB","SPK","GOV","INF","JOB","BIZ","HOL"},MATCH(INDEX(Events!$E$5:$E$304,$AD21),{"Central bank","CB speech","Government","Inflation","Jobs","Growth & business","Holiday"},0)),"?")) | E21: =IF($AD21="","",IF(INDEX(Events!$D$5:$D$304,$AD21)="High","● ",IF(INDEX(Events!$D$5:$D$304,$AD21)="Medium","○ "," "))&IF(INDEX(Events!$B$5:$B$304,$AD21)="","all day",TEXT(INDEX(Events!$B$5:$B$304,$AD21),"hh:mm"))&" "&INDEX(Events!$C$5:$C$304,$AD21)&" "&INDEX(Events!$F$5:$F$304,$AD21)) | F21: =IF($AE21="","",IFERROR(INDEX({"CB","SPK","GOV","INF","JOB","BIZ","HOL"},MATCH(INDEX(Events!$E$5:$E$304,$AE21),{"Central bank","CB speech","Government","Inflation","Jobs","Growth & business","Holiday"},0)),"?")) | G21: =IF($AE21="","",IF(INDEX(Events!$D$5:$D$304,$AE21)="High","● ",IF(INDEX(Events!$D$5:$D$304,$AE21)="Medium","○ "," "))&IF(INDEX(Events!$B$5:$B$304,$AE21)="","all day",TEXT(INDEX(Events!$B$5:$B$304,$AE21),"hh:mm"))&" "&INDEX(Events!$C$5:$C$304,$AE21)&" "&INDEX(Events!$F$5:$F$304,$AE21)) | H21: =IF($AF21="","",IFERROR(INDEX({"CB","SPK","GOV","INF","JOB","BIZ","HOL"},MATCH(INDEX(Events!$E$5:$E$304,$AF21),{"Central bank","CB speech","Government","Inflation","Jobs","Growth & business","Holiday"},0)),"?")) -> JOB | I21: =IF($AF21="","",IF(INDEX(Events!$D$5:$D$304,$AF21)="High","● ",IF(INDEX(Events!$D$5:$D$304,$AF21)="Medium","○ "," "))&IF(INDEX(Events!$B$5:$B$304,$AF21)="","all day",TEXT(INDEX(Events!$B$5:$B$304,$AF21),"hh:mm"))&" "&INDEX(Events!$C$5:$C$304,$AF21)&" "&INDEX(Events!$F$5:$F$304,$AF21)) -> ○ 14:30 USD Unemployment Claims | J21: =IF($AG21="","",IFERROR(INDEX({"CB","SPK","GOV","INF","JOB","BIZ","HOL"},MATCH(INDEX(Events!$E$5:$E$304,$AG21),{"Central bank","CB speech","Government","Inflation","Jobs","Growth & business","Holiday"},0)),"?")) | K21: =IF($AG21="","",IF(INDEX(Events!$D$5:$D$304,$AG21)="High","● ",IF(INDEX(Events!$D$5:$D$304,$AG21)="Medium","○ "," "))&IF(INDEX(Events!$B$5:$B$304,$AG21)="","all day",TEXT(INDEX(Events!$B$5:$B$304,$AG21),"hh:mm"))&" "&INDEX(Events!$C$5:$C$304,$AG21)&" "&INDEX(Events!$F$5:$F$304,$AG21)) | M21: =(EDATE(DATE(YEAR($H$6),MONTH($H$6),1),2)-WEEKDAY(EDATE(DATE(YEAR($H$6),MONTH($H$6),1),2),3))+0 -> 46356 | N21: =(EDATE(DATE(YEAR($H$6),MONTH($H$6),1),2)-WEEKDAY(EDATE(DATE(YEAR($H$6),MONTH($H$6),1),2),3))+1 -> 46357 | O21: =(EDATE(DATE(YEAR($H$6),MONTH($H$6),1),2)-WEEKDAY(EDATE(DATE(YEAR($H$6),MONTH($H$6),1),2),3))+2 -> 46358 | P21: =(EDATE(DATE(YEAR($H$6),MONTH($H$6),1),2)-WEEKDAY(EDATE(DATE(YEAR($H$6),MONTH($H$6),1),2),3))+3 -> 46359 | Q21: =(EDATE(DATE(YEAR($H$6),MONTH($H$6),1),2)-WEEKDAY(EDATE(DATE(YEAR($H$6),MONTH($H$6),1),2),3))+4 -> 46360 | R21: =(EDATE(DATE(YEAR($H$6),MONTH($H$6),1),2)-WEEKDAY(EDATE(DATE(YEAR($H$6),MONTH($H$6),1),2),3))+5 -> 46361 | S21: =(EDATE(DATE(YEAR($H$6),MONTH($H$6),1),2)-WEEKDAY(EDATE(DATE(YEAR($H$6),MONTH($H$6),1),2),3))+6 -> 46362 | U21: =(EDATE(DATE(YEAR($H$6),MONTH($H$6),1),3)-WEEKDAY(EDATE(DATE(YEAR($H$6),MONTH($H$6),1),3),3))+0 -> 46384 | V21: =(EDATE(DATE(YEAR($H$6),MONTH($H$6),1),3)-WEEKDAY(EDATE(DATE(YEAR($H$6),MONTH($H$6),1),3),3))+1 -> 46385 | W21: =(EDATE(DATE(YEAR($H$6),MONTH($H$6),1),3)-WEEKDAY(EDATE(DATE(YEAR($H$6),MONTH($H$6),1),3),3))+2 -> 46386 | X21: =(EDATE(DATE(YEAR($H$6),MONTH($H$6),1),3)-WEEKDAY(EDATE(DATE(YEAR($H$6),MONTH($H$6),1),3),3))+3 -> 46387 | Y21: =(EDATE(DATE(YEAR($H$6),MONTH($H$6),1),3)-WEEKDAY(EDATE(DATE(YEAR($H$6),MONTH($H$6),1),3),3))+4 -> 46388 | Z21: =(EDATE(DATE(YEAR($H$6),MONTH($H$6),1),3)-WEEKDAY(EDATE(DATE(YEAR($H$6),MONTH($H$6),1),3),3))+5 -> 46389 | AA21: =(EDATE(DATE(YEAR($H$6),MONTH($H$6),1),3)-WEEKDAY(EDATE(DATE(YEAR($H$6),MONTH($H$6),1),3),3))+6 -> 46390 | AC21: =IFERROR(MATCH(TEXT(B$10,"yyyymmdd")&"|"&$A21,Events!$M$5:$M$304,0),"") | AD21: =IFERROR(MATCH(TEXT(D$10,"yyyymmdd")&"|"&$A21,Events!$M$5:$M$304,0),"") | AE21: =IFERROR(MATCH(TEXT(F$10,"yyyymmdd")&"|"&$A21,Events!$M$5:$M$304,0),"") | AF21: =IFERROR(MATCH(TEXT(H$10,"yyyymmdd")&"|"&$A21,Events!$M$5:$M$304,0),"") -> 43 | AG21: =IFERROR(MATCH(TEXT(J$10,"yyyymmdd")&"|"&$A21,Events!$M$5:$M$304,0),"")
A22: 12 | B22: =IF($AC22="","",IFERROR(INDEX({"CB","SPK","GOV","INF","JOB","BIZ","HOL"},MATCH(INDEX(Events!$E$5:$E$304,$AC22),{"Central bank","CB speech","Government","Inflation","Jobs","Growth & business","Holiday"},0)),"?")) | C22: =IF($AC22="","",IF(INDEX(Events!$D$5:$D$304,$AC22)="High","● ",IF(INDEX(Events!$D$5:$D$304,$AC22)="Medium","○ "," "))&IF(INDEX(Events!$B$5:$B$304,$AC22)="","all day",TEXT(INDEX(Events!$B$5:$B$304,$AC22),"hh:mm"))&" "&INDEX(Events!$C$5:$C$304,$AC22)&" "&INDEX(Events!$F$5:$F$304,$AC22)) | D22: =IF($AD22="","",IFERROR(INDEX({"CB","SPK","GOV","INF","JOB","BIZ","HOL"},MATCH(INDEX(Events!$E$5:$E$304,$AD22),{"Central bank","CB speech","Government","Inflation","Jobs","Growth & business","Holiday"},0)),"?")) | E22: =IF($AD22="","",IF(INDEX(Events!$D$5:$D$304,$AD22)="High","● ",IF(INDEX(Events!$D$5:$D$304,$AD22)="Medium","○ "," "))&IF(INDEX(Events!$B$5:$B$304,$AD22)="","all day",TEXT(INDEX(Events!$B$5:$B$304,$AD22),"hh:mm"))&" "&INDEX(Events!$C$5:$C$304,$AD22)&" "&INDEX(Events!$F$5:$F$304,$AD22)) | F22: =IF($AE22="","",IFERROR(INDEX({"CB","SPK","GOV","INF","JOB","BIZ","HOL"},MATCH(INDEX(Events!$E$5:$E$304,$AE22),{"Central bank","CB speech","Government","Inflation","Jobs","Growth & business","Holiday"},0)),"?")) | G22: =IF($AE22="","",IF(INDEX(Events!$D$5:$D$304,$AE22)="High","● ",IF(INDEX(Events!$D$5:$D$304,$AE22)="Medium","○ "," "))&IF(INDEX(Events!$B$5:$B$304,$AE22)="","all day",TEXT(INDEX(Events!$B$5:$B$304,$AE22),"hh:mm"))&" "&INDEX(Events!$C$5:$C$304,$AE22)&" "&INDEX(Events!$F$5:$F$304,$AE22)) | H22: =IF($AF22="","",IFERROR(INDEX({"CB","SPK","GOV","INF","JOB","BIZ","HOL"},MATCH(INDEX(Events!$E$5:$E$304,$AF22),{"Central bank","CB speech","Government","Inflation","Jobs","Growth & business","Holiday"},0)),"?")) | I22: =IF($AF22="","",IF(INDEX(Events!$D$5:$D$304,$AF22)="High","● ",IF(INDEX(Events!$D$5:$D$304,$AF22)="Medium","○ "," "))&IF(INDEX(Events!$B$5:$B$304,$AF22)="","all day",TEXT(INDEX(Events!$B$5:$B$304,$AF22),"hh:mm"))&" "&INDEX(Events!$C$5:$C$304,$AF22)&" "&INDEX(Events!$F$5:$F$304,$AF22)) | J22: =IF($AG22="","",IFERROR(INDEX({"CB","SPK","GOV","INF","JOB","BIZ","HOL"},MATCH(INDEX(Events!$E$5:$E$304,$AG22),{"Central bank","CB speech","Government","Inflation","Jobs","Growth & business","Holiday"},0)),"?")) | K22: =IF($AG22="","",IF(INDEX(Events!$D$5:$D$304,$AG22)="High","● ",IF(INDEX(Events!$D$5:$D$304,$AG22)="Medium","○ "," "))&IF(INDEX(Events!$B$5:$B$304,$AG22)="","all day",TEXT(INDEX(Events!$B$5:$B$304,$AG22),"hh:mm"))&" "&INDEX(Events!$C$5:$C$304,$AG22)&" "&INDEX(Events!$F$5:$F$304,$AG22)) | M22: =(EDATE(DATE(YEAR($H$6),MONTH($H$6),1),2)-WEEKDAY(EDATE(DATE(YEAR($H$6),MONTH($H$6),1),2),3))+7 -> 46363 | N22: =(EDATE(DATE(YEAR($H$6),MONTH($H$6),1),2)-WEEKDAY(EDATE(DATE(YEAR($H$6),MONTH($H$6),1),2),3))+8 -> 46364 | O22: =(EDATE(DATE(YEAR($H$6),MONTH($H$6),1),2)-WEEKDAY(EDATE(DATE(YEAR($H$6),MONTH($H$6),1),2),3))+9 -> 46365 | P22: =(EDATE(DATE(YEAR($H$6),MONTH($H$6),1),2)-WEEKDAY(EDATE(DATE(YEAR($H$6),MONTH($H$6),1),2),3))+10 -> 46366 | Q22: =(EDATE(DATE(YEAR($H$6),MONTH($H$6),1),2)-WEEKDAY(EDATE(DATE(YEAR($H$6),MONTH($H$6),1),2),3))+11 -> 46367 | R22: =(EDATE(DATE(YEAR($H$6),MONTH($H$6),1),2)-WEEKDAY(EDATE(DATE(YEAR($H$6),MONTH($H$6),1),2),3))+12 -> 46368 | S22: =(EDATE(DATE(YEAR($H$6),MONTH($H$6),1),2)-WEEKDAY(EDATE(DATE(YEAR($H$6),MONTH($H$6),1),2),3))+13 -> 46369 | U22: =(EDATE(DATE(YEAR($H$6),MONTH($H$6),1),3)-WEEKDAY(EDATE(DATE(YEAR($H$6),MONTH($H$6),1),3),3))+7 -> 46391 | V22: =(EDATE(DATE(YEAR($H$6),MONTH($H$6),1),3)-WEEKDAY(EDATE(DATE(YEAR($H$6),MONTH($H$6),1),3),3))+8 -> 46392 | W22: =(EDATE(DATE(YEAR($H$6),MONTH($H$6),1),3)-WEEKDAY(EDATE(DATE(YEAR($H$6),MONTH($H$6),1),3),3))+9 -> 46393 | X22: =(EDATE(DATE(YEAR($H$6),MONTH($H$6),1),3)-WEEKDAY(EDATE(DATE(YEAR($H$6),MONTH($H$6),1),3),3))+10 -> 46394 | Y22: =(EDATE(DATE(YEAR($H$6),MONTH($H$6),1),3)-WEEKDAY(EDATE(DATE(YEAR($H$6),MONTH($H$6),1),3),3))+11 -> 46395 | Z22: =(EDATE(DATE(YEAR($H$6),MONTH($H$6),1),3)-WEEKDAY(EDATE(DATE(YEAR($H$6),MONTH($H$6),1),3),3))+12 -> 46396 | AA22: =(EDATE(DATE(YEAR($H$6),MONTH($H$6),1),3)-WEEKDAY(EDATE(DATE(YEAR($H$6),MONTH($H$6),1),3),3))+13 -> 46397 | AC22: =IFERROR(MATCH(TEXT(B$10,"yyyymmdd")&"|"&$A22,Events!$M$5:$M$304,0),"") | AD22: =IFERROR(MATCH(TEXT(D$10,"yyyymmdd")&"|"&$A22,Events!$M$5:$M$304,0),"") | AE22: =IFERROR(MATCH(TEXT(F$10,"yyyymmdd")&"|"&$A22,Events!$M$5:$M$304,0),"") | AF22: =IFERROR(MATCH(TEXT(H$10,"yyyymmdd")&"|"&$A22,Events!$M$5:$M$304,0),"") | AG22: =IFERROR(MATCH(TEXT(J$10,"yyyymmdd")&"|"&$A22,Events!$M$5:$M$304,0),"")
B23: ● high impact ○ medium impact · left tag = type of event, event colour = country · yellow = today · pick “All” above to add low-impact events; change the week number to look ahead. | M23: =(EDATE(DATE(YEAR($H$6),MONTH($H$6),1),2)-WEEKDAY(EDATE(DATE(YEAR($H$6),MONTH($H$6),1),2),3))+14 -> 46370 | N23: =(EDATE(DATE(YEAR($H$6),MONTH($H$6),1),2)-WEEKDAY(EDATE(DATE(YEAR($H$6),MONTH($H$6),1),2),3))+15 -> 46371 | O23: =(EDATE(DATE(YEAR($H$6),MONTH($H$6),1),2)-WEEKDAY(EDATE(DATE(YEAR($H$6),MONTH($H$6),1),2),3))+16 -> 46372 | P23: =(EDATE(DATE(YEAR($H$6),MONTH($H$6),1),2)-WEEKDAY(EDATE(DATE(YEAR($H$6),MONTH($H$6),1),2),3))+17 -> 46373 | Q23: =(EDATE(DATE(YEAR($H$6),MONTH($H$6),1),2)-WEEKDAY(EDATE(DATE(YEAR($H$6),MONTH($H$6),1),2),3))+18 -> 46374 | R23: =(EDATE(DATE(YEAR($H$6),MONTH($H$6),1),2)-WEEKDAY(EDATE(DATE(YEAR($H$6),MONTH($H$6),1),2),3))+19 -> 46375 | S23: =(EDATE(DATE(YEAR($H$6),MONTH($H$6),1),2)-WEEKDAY(EDATE(DATE(YEAR($H$6),MONTH($H$6),1),2),3))+20 -> 46376 | U23: =(EDATE(DATE(YEAR($H$6),MONTH($H$6),1),3)-WEEKDAY(EDATE(DATE(YEAR($H$6),MONTH($H$6),1),3),3))+14 -> 46398 | V23: =(EDATE(DATE(YEAR($H$6),MONTH($H$6),1),3)-WEEKDAY(EDATE(DATE(YEAR($H$6),MONTH($H$6),1),3),3))+15 -> 46399 | W23: =(EDATE(DATE(YEAR($H$6),MONTH($H$6),1),3)-WEEKDAY(EDATE(DATE(YEAR($H$6),MONTH($H$6),1),3),3))+16 -> 46400 | X23: =(EDATE(DATE(YEAR($H$6),MONTH($H$6),1),3)-WEEKDAY(EDATE(DATE(YEAR($H$6),MONTH($H$6),1),3),3))+17 -> 46401 | Y23: =(EDATE(DATE(YEAR($H$6),MONTH($H$6),1),3)-WEEKDAY(EDATE(DATE(YEAR($H$6),MONTH($H$6),1),3),3))+18 -> 46402 | Z23: =(EDATE(DATE(YEAR($H$6),MONTH($H$6),1),3)-WEEKDAY(EDATE(DATE(YEAR($H$6),MONTH($H$6),1),3),3))+19 -> 46403 | AA23: =(EDATE(DATE(YEAR($H$6),MONTH($H$6),1),3)-WEEKDAY(EDATE(DATE(YEAR($H$6),MONTH($H$6),1),3),3))+20 -> 46404
